Workbook

Sheet Totals
B1: Minutes | C1: Goals | D1: Assists | E1: Key Pass | F1: Start CA | G1: Outplay | H1: Cross | I1: 1v1 | J1: Header | K1: SP Earned | L1: Shots Off | M1: Shots On | N1: Off Totals | O1: Off A/m | P1: Tackle | Q1: Interception | R1: FH Regain | S1: Block | T1: Clearance | U1: Separation | V1: Header | W1: Stop FWD | X1: Def Totals | Y1: Def A/m | Z1: Total Act | AA1: Total A/m | AC1: Offense | AT1: Defense
A2: addy | B2: =Louisville!B2+SD!B2+ND!B2+Alabama!B2+UNO!B2+KSU!B2+Indiana!B2+Iowa!B2+Washington!B2+MSU!B2+Michigan!B2+Wisconsin!B2+Maryland!B2+Rutgers!B2+Illinois!B2+USC!B2+UCLA!B2+Purdue!B2 -> 82 | C2: =Louisville!C2+SD!C2+ND!C2+Alabama!C2+UNO!C2+KSU!C2+Indiana!C2+Iowa!C2+Washington!C2+MSU!C2+Michigan!C2+Wisconsin!C2+Maryland!C2+Rutgers!C2+Illinois!C2+USC!C2+UCLA!C2+Purdue!C2 -> 0 | D2: =Louisville!D2+SD!D2+ND!D2+Alabama!D2+UNO!D2+KSU!D2+Indiana!D2+Iowa!D2+Washington!D2+MSU!D2+Michigan!D2+Wisconsin!D2+Maryland!D2+Rutgers!D2+Illinois!D2+USC!D2+UCLA!D2+Purdue!D2 -> 0 | E2: =Louisville!E2+SD!E2+ND!E2+Alabama!E2+UNO!E2+KSU!E2+Indiana!E2+Iowa!E2+Washington!E2+MSU!E2+Michigan!E2+Wisconsin!E2+Maryland!E2+Rutgers!E2+Illinois!E2+USC!E2+UCLA!E2+Purdue!E2 -> 0 | F2: =Louisville!F2+SD!F2+ND!F2+Alabama!F2+UNO!F2+KSU!F2+Indiana!F2+Iowa!F2+Washington!F2+MSU!F2+Michigan!F2+Wisconsin!F2+Maryland!F2+Rutgers!F2+Illinois!F2+USC!F2+UCLA!F2+Purdue!F2 -> 6 | G2: =Louisville!G2+SD!G2+ND!G2+Alabama!G2+UNO!G2+KSU!G2+Indiana!G2+Iowa!G2+Washington!G2+MSU!G2+Michigan!G2+Wisconsin!G2+Maryland!G2+Rutgers!G2+Illinois!G2+USC!G2+UCLA!G2+Purdue!G2 -> 0 | H2: =Louisville!H2+SD!H2+ND!H2+Alabama!H2+UNO!H2+KSU!H2+Indiana!H2+Iowa!H2+Washington!H2+MSU!H2+Michigan!H2+Wisconsin!H2+Maryland!H2+Rutgers!H2+Illinois!H2+USC!H2+UCLA!H2+Purdue!H2 -> 0 | I2: =Louisville!I2+SD!I2+ND!I2+Alabama!I2+UNO!I2+KSU!I2+Indiana!I2+Iowa!I2+Washington!I2+MSU!I2+Michigan!I2+Wisconsin!I2+Maryland!I2+Rutgers!I2+Illinois!I2+USC!I2+UCLA!I2+Purdue!I2 -> 1 | ... N2: =Louisville!N2+SD!N2+ND!N2+Alabama!N2+UNO!N2+KSU!N2+Indiana!N2+Iowa!N2+Washington!N2+MSU!N2+Michigan!N2+Wisconsin!N2+Maryland!N2+Rutgers!N2+Illinois!N2+USC!N2+UCLA!N2+Purdue!N2 -> 7 | O2: =IFERROR(N2/B2,0) -> 0.085365854 | P2: =Louisville!P2+SD!P2+ND!P2+Alabama!P2+UNO!P2+KSU!P2+Indiana!P2+Iowa!P2+Washington!P2+MSU!P2+Michigan!P2+Wisconsin!P2+Maryland!P2+Rutgers!P2+Illinois!P2+USC!P2+UCLA!P2+Purdue!P2 -> 7 | Q2: =Louisville!Q2+SD!Q2+ND!Q2+Alabama!Q2+UNO!Q2+KSU!Q2+Indiana!Q2+Iowa!Q2+Washington!Q2+MSU!Q2+Michigan!Q2+Wisconsin!Q2+Maryland!Q2+Rutgers!Q2+Illinois!Q2+USC!Q2+UCLA!Q2+Purdue!Q2 -> 6 | R2: =Louisville!R2+SD!R2+ND!R2+Alabama!R2+UNO!R2+KSU!R2+Indiana!R2+Iowa!R2+Washington!R2+MSU!R2+Michigan!R2+Wisconsin!R2+Maryland!R2+Rutgers!R2+Illinois!R2+USC!R2+UCLA!R2+Purdue!R2 -> 3 | S2: =Louisville!S2+SD!S2+ND!S2+Alabama!S2+UNO!S2+KSU!S2+Indiana!S2+Iowa!S2+Washington!S2+MSU!S2+Michigan!S2+Wisconsin!S2+Maryland!S2+Rutgers!S2+Illinois!S2+USC!S2+UCLA!S2+Purdue!S2 -> 0 | T2: =Louisville!T2+SD!T2+ND!T2+Alabama!T2+UNO!T2+KSU!T2+Indiana!T2+Iowa!T2+Washington!T2+MSU!T2+Michigan!T2+Wisconsin!T2+Maryland!T2+Rutgers!T2+Illinois!T2+USC!T2+UCLA!T2+Purdue!T2 -> 0 | U2: =Louisville!U2+SD!U2+ND!U2+Alabama!U2+UNO!U2+KSU!U2+Indiana!U2+Iowa!U2+Washington!U2+MSU!U2+Michigan!U2+Wisconsin!U2+Maryland!U2+Rutgers!U2+Illinois!U2+USC!U2+UCLA!U2+Purdue!U2 -> 0 | V2: =Louisville!V2+SD!V2+ND!V2+Alabama!V2+UNO!V2+KSU!V2+Indiana!V2+Iowa!V2+Washington!V2+MSU!V2+Michigan!V2+Wisconsin!V2+Maryland!V2+Rutgers!V2+Illinois!V2+USC!V2+UCLA!V2+Purdue!V2 -> 2 | W2: =Louisville!W2+SD!W2+ND!W2+Alabama!W2+UNO!W2+KSU!W2+Indiana!W2+Iowa!W2+Washington!W2+MSU!W2+Michigan!W2+Wisconsin!W2+Maryland!W2+Rutgers!W2+Illinois!W2+USC!W2+UCLA!W2+Purdue!W2 -> 11 | X2: =Louisville!X2+SD!X2+ND!X2+Alabama!X2+UNO!X2+KSU!X2+Indiana!X2+Iowa!X2+Washington!X2+MSU!X2+Michigan!X2+Wisconsin!X2+Maryland!X2+Rutgers!X2+Illinois!X2+USC!X2+UCLA!X2+Purdue!X2 -> 29 | Y2: =IFERROR(X2/B2,0) -> 0.35365854 | Z2: =Louisville!Z2+SD!Z2+ND!Z2+Alabama!Z2+UNO!Z2+KSU!Z2+Indiana!Z2+Iowa!Z2+Washington!Z2+MSU!Z2+Michigan!Z2+Wisconsin!Z2+Maryland!Z2+Rutgers!Z2+Illinois!Z2+USC!Z2+UCLA!Z2+Purdue!Z2 -> 36 | AA2: =IFERROR(Z2/B2,0) -> 0.43902439 | AC2: ="<tr><td>Jones</td><td>"&B2&"</td><td>"&C2&"</td><td>"&D2&"</td><td>"&E2&"</td><td>"&F2&"</td><td>"&G2&"</td><td>"&H2&"</td><td>"&I2&"</td><td>"&J2&"</td><td>"&K2&"</td><td>"&L2&"</td><td>"&M2&"</td><td>"&N2&"</td><td>"&TEXT(O2,"0.00")&"</td><td>"&Z2&"</td><td>"&TEXT(AA2,"0.00")&"</td></tr>" -> <tr><td>Jones</td><td>82</td><td>0</td><td>0</td><td>0</td><td>6</td><td>0</td><td>0</td><td>1</td><td>0</td><td>0</td><td>0</td><td>0</td><td>7</td><td>0.09</td><td>36</td><td>0.44</td></tr> | AT2: ="<tr><td>Jones</td><td>"&B2&"</td><td>"&P2&"</td><td>"&Q2&"</td><td>"&R2&"</td><td>"&S2&"</td><td>"&T2&"</td><td>"&U2&"</td><td>"&V2&"</td><td>"&W2&"</td><td>"&X2&"</td><td>"&TEXT(Y2,"0.00")&"</td><td>"&Z2&"</td><td>"&TEXT(AA2,"0.00")&"</td></tr>" -> <tr><td>Jones</td><td>82</td><td>7</td><td>6</td><td>3</td><td>0</td><td>0</td><td>0</td><td>2</td><td>11</td><td>29</td><td>0.35</td><td>36</td><td>0.44</td></tr>
A3: ally | B3: =Louisville!B3+SD!B3+ND!B3+Alabama!B3+UNO!B3+KSU!B3+Indiana!B3+Iowa!B3+Washington!B3+MSU!B3+Michigan!B3+Wisconsin!B3+Maryland!B3+Rutgers!B3+Illinois!B3+USC!B3+UCLA!B3+Purdue!B3 -> 80 | C3: =Louisville!C3+SD!C3+ND!C3+Alabama!C3+UNO!C3+KSU!C3+Indiana!C3+Iowa!C3+Washington!C3+MSU!C3+Michigan!C3+Wisconsin!C3+Maryland!C3+Rutgers!C3+Illinois!C3+USC!C3+UCLA!C3+Purdue!C3 -> 0 | D3: =Louisville!D3+SD!D3+ND!D3+Alabama!D3+UNO!D3+KSU!D3+Indiana!D3+Iowa!D3+Washington!D3+MSU!D3+Michigan!D3+Wisconsin!D3+Maryland!D3+Rutgers!D3+Illinois!D3+USC!D3+UCLA!D3+Purdue!D3 -> 0 | E3: =Louisville!E3+SD!E3+ND!E3+Alabama!E3+UNO!E3+KSU!E3+Indiana!E3+Iowa!E3+Washington!E3+MSU!E3+Michigan!E3+Wisconsin!E3+Maryland!E3+Rutgers!E3+Illinois!E3+USC!E3+UCLA!E3+Purdue!E3 -> 0 | F3: =Louisville!F3+SD!F3+ND!F3+Alabama!F3+UNO!F3+KSU!F3+Indiana!F3+Iowa!F3+Washington!F3+MSU!F3+Michigan!F3+Wisconsin!F3+Maryland!F3+Rutgers!F3+Illinois!F3+USC!F3+UCLA!F3+Purdue!F3 -> 2 | G3: =Louisville!G3+SD!G3+ND!G3+Alabama!G3+UNO!G3+KSU!G3+Indiana!G3+Iowa!G3+Washington!G3+MSU!G3+Michigan!G3+Wisconsin!G3+Maryland!G3+Rutgers!G3+Illinois!G3+USC!G3+UCLA!G3+Purdue!G3 -> 1 | H3: =Louisville!H3+SD!H3+ND!H3+Alabama!H3+UNO!H3+KSU!H3+Indiana!H3+Iowa!H3+Washington!H3+MSU!H3+Michigan!H3+Wisconsin!H3+Maryland!H3+Rutgers!H3+Illinois!H3+USC!H3+UCLA!H3+Purdue!H3 -> 1 | I3: =Louisville!I3+SD!I3+ND!I3+Alabama!I3+UNO!I3+KSU!I3+Indiana!I3+Iowa!I3+Washington!I3+MSU!I3+Michigan!I3+Wisconsin!I3+Maryland!I3+Rutgers!I3+Illinois!I3+USC!I3+UCLA!I3+Purdue!I3 -> 0 | ... N3: =Louisville!N3+SD!N3+ND!N3+Alabama!N3+UNO!N3+KSU!N3+Indiana!N3+Iowa!N3+Washington!N3+MSU!N3+Michigan!N3+Wisconsin!N3+Maryland!N3+Rutgers!N3+Illinois!N3+USC!N3+UCLA!N3+Purdue!N3 -> 8 | O3: =IFERROR(N3/B3,0) -> 0.1 | P3: =Louisville!P3+SD!P3+ND!P3+Alabama!P3+UNO!P3+KSU!P3+Indiana!P3+Iowa!P3+Washington!P3+MSU!P3+Michigan!P3+Wisconsin!P3+Maryland!P3+Rutgers!P3+Illinois!P3+USC!P3+UCLA!P3+Purdue!P3 -> 3 | Q3: =Louisville!Q3+SD!Q3+ND!Q3+Alabama!Q3+UNO!Q3+KSU!Q3+Indiana!Q3+Iowa!Q3+Washington!Q3+MSU!Q3+Michigan!Q3+Wisconsin!Q3+Maryland!Q3+Rutgers!Q3+Illinois!Q3+USC!Q3+UCLA!Q3+Purdue!Q3 -> 3 | R3: =Louisville!R3+SD!R3+ND!R3+Alabama!R3+UNO!R3+KSU!R3+Indiana!R3+Iowa!R3+Washington!R3+MSU!R3+Michigan!R3+Wisconsin!R3+Maryland!R3+Rutgers!R3+Illinois!R3+USC!R3+UCLA!R3+Purdue!R3 -> 1 | S3: =Louisville!S3+SD!S3+ND!S3+Alabama!S3+UNO!S3+KSU!S3+Indiana!S3+Iowa!S3+Washington!S3+MSU!S3+Michigan!S3+Wisconsin!S3+Maryland!S3+Rutgers!S3+Illinois!S3+USC!S3+UCLA!S3+Purdue!S3 -> 0 | T3: =Louisville!T3+SD!T3+ND!T3+Alabama!T3+UNO!T3+KSU!T3+Indiana!T3+Iowa!T3+Washington!T3+MSU!T3+Michigan!T3+Wisconsin!T3+Maryland!T3+Rutgers!T3+Illinois!T3+USC!T3+UCLA!T3+Purdue!T3 -> 0 | U3: =Louisville!U3+SD!U3+ND!U3+Alabama!U3+UNO!U3+KSU!U3+Indiana!U3+Iowa!U3+Washington!U3+MSU!U3+Michigan!U3+Wisconsin!U3+Maryland!U3+Rutgers!U3+Illinois!U3+USC!U3+UCLA!U3+Purdue!U3 -> 2 | V3: =Louisville!V3+SD!V3+ND!V3+Alabama!V3+UNO!V3+KSU!V3+Indiana!V3+Iowa!V3+Washington!V3+MSU!V3+Michigan!V3+Wisconsin!V3+Maryland!V3+Rutgers!V3+Illinois!V3+USC!V3+UCLA!V3+Purdue!V3 -> 0 | W3: =Louisville!W3+SD!W3+ND!W3+Alabama!W3+UNO!W3+KSU!W3+Indiana!W3+Iowa!W3+Washington!W3+MSU!W3+Michigan!W3+Wisconsin!W3+Maryland!W3+Rutgers!W3+Illinois!W3+USC!W3+UCLA!W3+Purdue!W3 -> 4 | X3: =Louisville!X3+SD!X3+ND!X3+Alabama!X3+UNO!X3+KSU!X3+Indiana!X3+Iowa!X3+Washington!X3+MSU!X3+Michigan!X3+Wisconsin!X3+Maryland!X3+Rutgers!X3+Illinois!X3+USC!X3+UCLA!X3+Purdue!X3 -> 13 | Y3: =IFERROR(X3/B3,0) -> 0.1625 | Z3: =Louisville!Z3+SD!Z3+ND!Z3+Alabama!Z3+UNO!Z3+KSU!Z3+Indiana!Z3+Iowa!Z3+Washington!Z3+MSU!Z3+Michigan!Z3+Wisconsin!Z3+Maryland!Z3+Rutgers!Z3+Illinois!Z3+USC!Z3+UCLA!Z3+Purdue!Z3 -> 21 | AA3: =IFERROR(Z3/B3,0) -> 0.2625 | AC3: ="<tr><td>Geraneo</td><td>"&B3&"</td><td>"&C3&"</td><td>"&D3&"</td><td>"&E3&"</td><td>"&F3&"</td><td>"&G3&"</td><td>"&H3&"</td><td>"&I3&"</td><td>"&J3&"</td><td>"&K3&"</td><td>"&L3&"</td><td>"&M3&"</td><td>"&N3&"</td><td>"&TEXT(O3,"0.00")&"</td><td>"&Z3&"</td><td>"&TEXT(AA3,"0.00")&"</td></tr>" -> <tr><td>Geraneo</td><td>80</td><td>0</td><td>0</td><td>0</td><td>2</td><td>1</td><td>1</td><td>0</td><td>2</td><td>1</td><td>1</td><td>1</td><td>8</td><td>0.10</td><td>21</td><td>0.26</td></tr> | AT3: ="<tr><td>Geraneo</td><td>"&B3&"</td><td>"&P3&"</td><td>"&Q3&"</td><td>"&R3&"</td><td>"&S3&"</td><td>"&T3&"</td><td>"&U3&"</td><td>"&V3&"</td><td>"&W3&"</td><td>"&X3&"</td><td>"&TEXT(Y3,"0.00")&"</td><td>"&Z3&"</td><td>"&TEXT(AA3,"0.00")&"</td></tr>" -> <tr><td>Geraneo</td><td>80</td><td>3</td><td>3</td><td>1</td><td>0</td><td>0</td><td>2</td><td>0</td><td>4</td><td>13</td><td>0.16</td><td>21</td><td>0.26</td></tr>
A4: ava | B4: =Louisville!B4+SD!B4+ND!B4+Alabama!B4+UNO!B4+KSU!B4+Indiana!B4+Iowa!B4+Washington!B4+MSU!B4+Michigan!B4+Wisconsin!B4+Maryland!B4+Rutgers!B4+Illinois!B4+USC!B4+UCLA!B4+Purdue!B4 -> 730 | C4: =Louisville!C4+SD!C4+ND!C4+Alabama!C4+UNO!C4+KSU!C4+Indiana!C4+Iowa!C4+Washington!C4+MSU!C4+Michigan!C4+Wisconsin!C4+Maryland!C4+Rutgers!C4+Illinois!C4+USC!C4+UCLA!C4+Purdue!C4 -> 3 | D4: =Louisville!D4+SD!D4+ND!D4+Alabama!D4+UNO!D4+KSU!D4+Indiana!D4+Iowa!D4+Washington!D4+MSU!D4+Michigan!D4+Wisconsin!D4+Maryland!D4+Rutgers!D4+Illinois!D4+USC!D4+UCLA!D4+Purdue!D4 -> 0 | E4: =Louisville!E4+SD!E4+ND!E4+Alabama!E4+UNO!E4+KSU!E4+Indiana!E4+Iowa!E4+Washington!E4+MSU!E4+Michigan!E4+Wisconsin!E4+Maryland!E4+Rutgers!E4+Illinois!E4+USC!E4+UCLA!E4+Purdue!E4 -> 3 | F4: =Louisville!F4+SD!F4+ND!F4+Alabama!F4+UNO!F4+KSU!F4+Indiana!F4+Iowa!F4+Washington!F4+MSU!F4+Michigan!F4+Wisconsin!F4+Maryland!F4+Rutgers!F4+Illinois!F4+USC!F4+UCLA!F4+Purdue!F4 -> 19 | G4: =Louisville!G4+SD!G4+ND!G4+Alabama!G4+UNO!G4+KSU!G4+Indiana!G4+Iowa!G4+Washington!G4+MSU!G4+Michigan!G4+Wisconsin!G4+Maryland!G4+Rutgers!G4+Illinois!G4+USC!G4+UCLA!G4+Purdue!G4 -> 5 | H4: =Louisville!H4+SD!H4+ND!H4+Alabama!H4+UNO!H4+KSU!H4+Indiana!H4+Iowa!H4+Washington!H4+MSU!H4+Michigan!H4+Wisconsin!H4+Maryland!H4+Rutgers!H4+Illinois!H4+USC!H4+UCLA!H4+Purdue!H4 -> 4 | I4: =Louisville!I4+SD!I4+ND!I4+Alabama!I4+UNO!I4+KSU!I4+Indiana!I4+Iowa!I4+Washington!I4+MSU!I4+Michigan!I4+Wisconsin!I4+Maryland!I4+Rutgers!I4+Illinois!I4+USC!I4+UCLA!I4+Purdue!I4 -> 5 | ... N4: =Louisville!N4+SD!N4+ND!N4+Alabama!N4+UNO!N4+KSU!N4+Indiana!N4+Iowa!N4+Washington!N4+MSU!N4+Michigan!N4+Wisconsin!N4+Maryland!N4+Rutgers!N4+Illinois!N4+USC!N4+UCLA!N4+Purdue!N4 -> 144 | O4: =IFERROR(N4/B4,0) -> 0.19726027 | P4: =Louisville!P4+SD!P4+ND!P4+Alabama!P4+UNO!P4+KSU!P4+Indiana!P4+Iowa!P4+Washington!P4+MSU!P4+Michigan!P4+Wisconsin!P4+Maryland!P4+Rutgers!P4+Illinois!P4+USC!P4+UCLA!P4+Purdue!P4 -> 9 | Q4: =Louisville!Q4+SD!Q4+ND!Q4+Alabama!Q4+UNO!Q4+KSU!Q4+Indiana!Q4+Iowa!Q4+Washington!Q4+MSU!Q4+Michigan!Q4+Wisconsin!Q4+Maryland!Q4+Rutgers!Q4+Illinois!Q4+USC!Q4+UCLA!Q4+Purdue!Q4 -> 17 | R4: =Louisville!R4+SD!R4+ND!R4+Alabama!R4+UNO!R4+KSU!R4+Indiana!R4+Iowa!R4+Washington!R4+MSU!R4+Michigan!R4+Wisconsin!R4+Maryland!R4+Rutgers!R4+Illinois!R4+USC!R4+UCLA!R4+Purdue!R4 -> 9 | S4: =Louisville!S4+SD!S4+ND!S4+Alabama!S4+UNO!S4+KSU!S4+Indiana!S4+Iowa!S4+Washington!S4+MSU!S4+Michigan!S4+Wisconsin!S4+Maryland!S4+Rutgers!S4+Illinois!S4+USC!S4+UCLA!S4+Purdue!S4 -> 1 | T4: =Louisville!T4+SD!T4+ND!T4+Alabama!T4+UNO!T4+KSU!T4+Indiana!T4+Iowa!T4+Washington!T4+MSU!T4+Michigan!T4+Wisconsin!T4+Maryland!T4+Rutgers!T4+Illinois!T4+USC!T4+UCLA!T4+Purdue!T4 -> 2 | U4: =Louisville!U4+SD!U4+ND!U4+Alabama!U4+UNO!U4+KSU!U4+Indiana!U4+Iowa!U4+Washington!U4+MSU!U4+Michigan!U4+Wisconsin!U4+Maryland!U4+Rutgers!U4+Illinois!U4+USC!U4+UCLA!U4+Purdue!U4 -> 5 | V4: =Louisville!V4+SD!V4+ND!V4+Alabama!V4+UNO!V4+KSU!V4+Indiana!V4+Iowa!V4+Washington!V4+MSU!V4+Michigan!V4+Wisconsin!V4+Maryland!V4+Rutgers!V4+Illinois!V4+USC!V4+UCLA!V4+Purdue!V4 -> 23 | W4: =Louisville!W4+SD!W4+ND!W4+Alabama!W4+UNO!W4+KSU!W4+Indiana!W4+Iowa!W4+Washington!W4+MSU!W4+Michigan!W4+Wisconsin!W4+Maryland!W4+Rutgers!W4+Illinois!W4+USC!W4+UCLA!W4+Purdue!W4 -> 28 | X4: =Louisville!X4+SD!X4+ND!X4+Alabama!X4+UNO!X4+KSU!X4+Indiana!X4+Iowa!X4+Washington!X4+MSU!X4+Michigan!X4+Wisconsin!X4+Maryland!X4+Rutgers!X4+Illinois!X4+USC!X4+UCLA!X4+Purdue!X4 -> 94 | Y4: =IFERROR(X4/B4,0) -> 0.12876712 | Z4: =Louisville!Z4+SD!Z4+ND!Z4+Alabama!Z4+UNO!Z4+KSU!Z4+Indiana!Z4+Iowa!Z4+Washington!Z4+MSU!Z4+Michigan!Z4+Wisconsin!Z4+Maryland!Z4+Rutgers!Z4+Illinois!Z4+USC!Z4+UCLA!Z4+Purdue!Z4 -> 238 | AA4: =IFERROR(Z4/B4,0) -> 0.3260274 | AC4: ="<tr><td>Makovicka</td><td>"&B4&"</td><td>"&C4&"</td><td>"&D4&"</td><td>"&E4&"</td><td>"&F4&"</td><td>"&G4&"</td><td>"&H4&"</td><td>"&I4&"</td><td>"&J4&"</td><td>"&K4&"</td><td>"&L4&"</td><td>"&M4&"</td><td>"&N4&"</td><td>"&TEXT(O4,"0.00")&"</td><td>"&Z4&"</td><td>"&TEXT(AA4,"0.00")&"</td></tr>" -> <tr><td>Makovicka</td><td>730</td><td>3</td><td>0</td><td>3</td><td>19</td><td>5</td><td>4</td><td>5</td><td>53</td><td>33</td><td>12</td><td>10</td><td>144</td><td>0.20</td><td>238</td><td>0.33</td></tr> | AT4: ="<tr><td>Makovicka</td><td>"&B4&"</td><td>"&P4&"</td><td>"&Q4&"</td><td>"&R4&"</td><td>"&S4&"</td><td>"&T4&"</td><td>"&U4&"</td><td>"&V4&"</td><td>"&W4&"</td><td>"&X4&"</td><td>"&TEXT(Y4,"0.00")&"</td><td>"&Z4&"</td><td>"&TEXT(AA4,"0.00")&"</td></tr>" -> <tr><td>Makovicka</td><td>730</td><td>9</td><td>17</td><td>9</td><td>1</td><td>2</td><td>5</td><td>23</td><td>28</td><td>94</td><td>0.13</td><td>238</td><td>0.33</td></tr>
A5: carson | B5: =Louisville!B5+SD!B5+ND!B5+Alabama!B5+UNO!B5+KSU!B5+Indiana!B5+Iowa!B5+Washington!B5+MSU!B5+Michigan!B5+Wisconsin!B5+Maryland!B5+Rutgers!B5+Illinois!B5+USC!B5+UCLA!B5+Purdue!B5 -> 452 | C5: =Louisville!C5+SD!C5+ND!C5+Alabama!C5+UNO!C5+KSU!C5+Indiana!C5+Iowa!C5+Washington!C5+MSU!C5+Michigan!C5+Wisconsin!C5+Maryland!C5+Rutgers!C5+Illinois!C5+USC!C5+UCLA!C5+Purdue!C5 -> 1 | D5: =Louisville!D5+SD!D5+ND!D5+Alabama!D5+UNO!D5+KSU!D5+Indiana!D5+Iowa!D5+Washington!D5+MSU!D5+Michigan!D5+Wisconsin!D5+Maryland!D5+Rutgers!D5+Illinois!D5+USC!D5+UCLA!D5+Purdue!D5 -> 0 | E5: =Louisville!E5+SD!E5+ND!E5+Alabama!E5+UNO!E5+KSU!E5+Indiana!E5+Iowa!E5+Washington!E5+MSU!E5+Michigan!E5+Wisconsin!E5+Maryland!E5+Rutgers!E5+Illinois!E5+USC!E5+UCLA!E5+Purdue!E5 -> 2 | F5: =Louisville!F5+SD!F5+ND!F5+Alabama!F5+UNO!F5+KSU!F5+Indiana!F5+Iowa!F5+Washington!F5+MSU!F5+Michigan!F5+Wisconsin!F5+Maryland!F5+Rutgers!F5+Illinois!F5+USC!F5+UCLA!F5+Purdue!F5 -> 15 | G5: =Louisville!G5+SD!G5+ND!G5+Alabama!G5+UNO!G5+KSU!G5+Indiana!G5+Iowa!G5+Washington!G5+MSU!G5+Michigan!G5+Wisconsin!G5+Maryland!G5+Rutgers!G5+Illinois!G5+USC!G5+UCLA!G5+Purdue!G5 -> 1 | H5: =Louisville!H5+SD!H5+ND!H5+Alabama!H5+UNO!H5+KSU!H5+Indiana!H5+Iowa!H5+Washington!H5+MSU!H5+Michigan!H5+Wisconsin!H5+Maryland!H5+Rutgers!H5+Illinois!H5+USC!H5+UCLA!H5+Purdue!H5 -> 10 | I5: =Louisville!I5+SD!I5+ND!I5+Alabama!I5+UNO!I5+KSU!I5+Indiana!I5+Iowa!I5+Washington!I5+MSU!I5+Michigan!I5+Wisconsin!I5+Maryland!I5+Rutgers!I5+Illinois!I5+USC!I5+UCLA!I5+Purdue!I5 -> 10 | ... N5: =Louisville!N5+SD!N5+ND!N5+Alabama!N5+UNO!N5+KSU!N5+Indiana!N5+Iowa!N5+Washington!N5+MSU!N5+Michigan!N5+Wisconsin!N5+Maryland!N5+Rutgers!N5+Illinois!N5+USC!N5+UCLA!N5+Purdue!N5 -> 70 | O5: =IFERROR(N5/B5,0) -> 0.15486726 | P5: =Louisville!P5+SD!P5+ND!P5+Alabama!P5+UNO!P5+KSU!P5+Indiana!P5+Iowa!P5+Washington!P5+MSU!P5+Michigan!P5+Wisconsin!P5+Maryland!P5+Rutgers!P5+Illinois!P5+USC!P5+UCLA!P5+Purdue!P5 -> 5 | Q5: =Louisville!Q5+SD!Q5+ND!Q5+Alabama!Q5+UNO!Q5+KSU!Q5+Indiana!Q5+Iowa!Q5+Washington!Q5+MSU!Q5+Michigan!Q5+Wisconsin!Q5+Maryland!Q5+Rutgers!Q5+Illinois!Q5+USC!Q5+UCLA!Q5+Purdue!Q5 -> 12 | R5: =Louisville!R5+SD!R5+ND!R5+Alabama!R5+UNO!R5+KSU!R5+Indiana!R5+Iowa!R5+Washington!R5+MSU!R5+Michigan!R5+Wisconsin!R5+Maryland!R5+Rutgers!R5+Illinois!R5+USC!R5+UCLA!R5+Purdue!R5 -> 7 | S5: =Louisville!S5+SD!S5+ND!S5+Alabama!S5+UNO!S5+KSU!S5+Indiana!S5+Iowa!S5+Washington!S5+MSU!S5+Michigan!S5+Wisconsin!S5+Maryland!S5+Rutgers!S5+Illinois!S5+USC!S5+UCLA!S5+Purdue!S5 -> 3 | T5: =Louisville!T5+SD!T5+ND!T5+Alabama!T5+UNO!T5+KSU!T5+Indiana!T5+Iowa!T5+Washington!T5+MSU!T5+Michigan!T5+Wisconsin!T5+Maryland!T5+Rutgers!T5+Illinois!T5+USC!T5+UCLA!T5+Purdue!T5 -> 6 | U5: =Louisville!U5+SD!U5+ND!U5+Alabama!U5+UNO!U5+KSU!U5+Indiana!U5+Iowa!U5+Washington!U5+MSU!U5+Michigan!U5+Wisconsin!U5+Maryland!U5+Rutgers!U5+Illinois!U5+USC!U5+UCLA!U5+Purdue!U5 -> 9 | V5: =Louisville!V5+SD!V5+ND!V5+Alabama!V5+UNO!V5+KSU!V5+Indiana!V5+Iowa!V5+Washington!V5+MSU!V5+Michigan!V5+Wisconsin!V5+Maryland!V5+Rutgers!V5+Illinois!V5+USC!V5+UCLA!V5+Purdue!V5 -> 5 | W5: =Louisville!W5+SD!W5+ND!W5+Alabama!W5+UNO!W5+KSU!W5+Indiana!W5+Iowa!W5+Washington!W5+MSU!W5+Michigan!W5+Wisconsin!W5+Maryland!W5+Rutgers!W5+Illinois!W5+USC!W5+UCLA!W5+Purdue!W5 -> 29 | X5: =Louisville!X5+SD!X5+ND!X5+Alabama!X5+UNO!X5+KSU!X5+Indiana!X5+Iowa!X5+Washington!X5+MSU!X5+Michigan!X5+Wisconsin!X5+Maryland!X5+Rutgers!X5+Illinois!X5+USC!X5+UCLA!X5+Purdue!X5 -> 76 | Y5: =IFERROR(X5/B5,0) -> 0.16814159 | Z5: =Louisville!Z5+SD!Z5+ND!Z5+Alabama!Z5+UNO!Z5+KSU!Z5+Indiana!Z5+Iowa!Z5+Washington!Z5+MSU!Z5+Michigan!Z5+Wisconsin!Z5+Maryland!Z5+Rutgers!Z5+Illinois!Z5+USC!Z5+UCLA!Z5+Purdue!Z5 -> 146 | AA5: =IFERROR(Z5/B5,0) -> 0.32300885 | AC5: ="<tr><td>Bohonek</td><td>"&B5&"</td><td>"&C5&"</td><td>"&D5&"</td><td>"&E5&"</td><td>"&F5&"</td><td>"&G5&"</td><td>"&H5&"</td><td>"&I5&"</td><td>"&J5&"</td><td>"&K5&"</td><td>"&L5&"</td><td>"&M5&"</td><td>"&N5&"</td><td>"&TEXT(O5,"0.00")&"</td><td>"&Z5&"</td><td>"&TEXT(AA5,"0.00")&"</td></tr>" -> <tr><td>Bohonek</td><td>452</td><td>1</td><td>0</td><td>2</td><td>15</td><td>1</td><td>10</td><td>10</td><td>15</td><td>7</td><td>5</td><td>5</td><td>70</td><td>0.15</td><td>146</td><td>0.32</td></tr> | AT5: ="<tr><td>Bohonek</td><td>"&B5&"</td><td>"&P5&"</td><td>"&Q5&"</td><td>"&R5&"</td><td>"&S5&"</td><td>"&T5&"</td><td>"&U5&"</td><td>"&V5&"</td><td>"&W5&"</td><td>"&X5&"</td><td>"&TEXT(Y5,"0.00")&"</td><td>"&Z5&"</td><td>"&TEXT(AA5,"0.00")&"</td></tr>" -> <tr><td>Bohonek</td><td>452</td><td>5</td><td>12</td><td>7</td><td>3</td><td>6</td><td>9</td><td>5</td><td>29</td><td>76</td><td>0.17</td><td>146</td><td>0.32</td></tr>
A6: charlie | B6: =Louisville!B6+SD!B6+ND!B6+Alabama!B6+UNO!B6+KSU!B6+Indiana!B6+Iowa!B6+Washington!B6+MSU!B6+Michigan!B6+Wisconsin!B6+Maryland!B6+Rutgers!B6+Illinois!B6+USC!B6+UCLA!B6+Purdue!B6 -> 77 | C6: =Louisville!C6+SD!C6+ND!C6+Alabama!C6+UNO!C6+KSU!C6+Indiana!C6+Iowa!C6+Washington!C6+MSU!C6+Michigan!C6+Wisconsin!C6+Maryland!C6+Rutgers!C6+Illinois!C6+USC!C6+UCLA!C6+Purdue!C6 -> 0 | D6: =Louisville!D6+SD!D6+ND!D6+Alabama!D6+UNO!D6+KSU!D6+Indiana!D6+Iowa!D6+Washington!D6+MSU!D6+Michigan!D6+Wisconsin!D6+Maryland!D6+Rutgers!D6+Illinois!D6+USC!D6+UCLA!D6+Purdue!D6 -> 0 | E6: =Louisville!E6+SD!E6+ND!E6+Alabama!E6+UNO!E6+KSU!E6+Indiana!E6+Iowa!E6+Washington!E6+MSU!E6+Michigan!E6+Wisconsin!E6+Maryland!E6+Rutgers!E6+Illinois!E6+USC!E6+UCLA!E6+Purdue!E6 -> 0 | F6: =Louisville!F6+SD!F6+ND!F6+Alabama!F6+UNO!F6+KSU!F6+Indiana!F6+Iowa!F6+Washington!F6+MSU!F6+Michigan!F6+Wisconsin!F6+Maryland!F6+Rutgers!F6+Illinois!F6+USC!F6+UCLA!F6+Purdue!F6 -> 0 | G6: =Louisville!G6+SD!G6+ND!G6+Alabama!G6+UNO!G6+KSU!G6+Indiana!G6+Iowa!G6+Washington!G6+MSU!G6+Michigan!G6+Wisconsin!G6+Maryland!G6+Rutgers!G6+Illinois!G6+USC!G6+UCLA!G6+Purdue!G6 -> 0 | H6: =Louisville!H6+SD!H6+ND!H6+Alabama!H6+UNO!H6+KSU!H6+Indiana!H6+Iowa!H6+Washington!H6+MSU!H6+Michigan!H6+Wisconsin!H6+Maryland!H6+Rutgers!H6+Illinois!H6+USC!H6+UCLA!H6+Purdue!H6 -> 2 | I6: =Louisville!I6+SD!I6+ND!I6+Alabama!I6+UNO!I6+KSU!I6+Indiana!I6+Iowa!I6+Washington!I6+MSU!I6+Michigan!I6+Wisconsin!I6+Maryland!I6+Rutgers!I6+Illinois!I6+USC!I6+UCLA!I6+Purdue!I6 -> 2 | ... N6: =Louisville!N6+SD!N6+ND!N6+Alabama!N6+UNO!N6+KSU!N6+Indiana!N6+Iowa!N6+Washington!N6+MSU!N6+Michigan!N6+Wisconsin!N6+Maryland!N6+Rutgers!N6+Illinois!N6+USC!N6+UCLA!N6+Purdue!N6 -> 6 | O6: =IFERROR(N6/B6,0) -> 0.077922078 | P6: =Louisville!P6+SD!P6+ND!P6+Alabama!P6+UNO!P6+KSU!P6+Indiana!P6+Iowa!P6+Washington!P6+MSU!P6+Michigan!P6+Wisconsin!P6+Maryland!P6+Rutgers!P6+Illinois!P6+USC!P6+UCLA!P6+Purdue!P6 -> 0 | Q6: =Louisville!Q6+SD!Q6+ND!Q6+Alabama!Q6+UNO!Q6+KSU!Q6+Indiana!Q6+Iowa!Q6+Washington!Q6+MSU!Q6+Michigan!Q6+Wisconsin!Q6+Maryland!Q6+Rutgers!Q6+Illinois!Q6+USC!Q6+UCLA!Q6+Purdue!Q6 -> 3 | R6: =Louisville!R6+SD!R6+ND!R6+Alabama!R6+UNO!R6+KSU!R6+Indiana!R6+Iowa!R6+Washington!R6+MSU!R6+Michigan!R6+Wisconsin!R6+Maryland!R6+Rutgers!R6+Illinois!R6+USC!R6+UCLA!R6+Purdue!R6 -> 1 | S6: =Louisville!S6+SD!S6+ND!S6+Alabama!S6+UNO!S6+KSU!S6+Indiana!S6+Iowa!S6+Washington!S6+MSU!S6+Michigan!S6+Wisconsin!S6+Maryland!S6+Rutgers!S6+Illinois!S6+USC!S6+UCLA!S6+Purdue!S6 -> 0 | T6: =Louisville!T6+SD!T6+ND!T6+Alabama!T6+UNO!T6+KSU!T6+Indiana!T6+Iowa!T6+Washington!T6+MSU!T6+Michigan!T6+Wisconsin!T6+Maryland!T6+Rutgers!T6+Illinois!T6+USC!T6+UCLA!T6+Purdue!T6 -> 0 | U6: =Louisville!U6+SD!U6+ND!U6+Alabama!U6+UNO!U6+KSU!U6+Indiana!U6+Iowa!U6+Washington!U6+MSU!U6+Michigan!U6+Wisconsin!U6+Maryland!U6+Rutgers!U6+Illinois!U6+USC!U6+UCLA!U6+Purdue!U6 -> 2 | V6: =Louisville!V6+SD!V6+ND!V6+Alabama!V6+UNO!V6+KSU!V6+Indiana!V6+Iowa!V6+Washington!V6+MSU!V6+Michigan!V6+Wisconsin!V6+Maryland!V6+Rutgers!V6+Illinois!V6+USC!V6+UCLA!V6+Purdue!V6 -> 1 | W6: =Louisville!W6+SD!W6+ND!W6+Alabama!W6+UNO!W6+KSU!W6+Indiana!W6+Iowa!W6+Washington!W6+MSU!W6+Michigan!W6+Wisconsin!W6+Maryland!W6+Rutgers!W6+Illinois!W6+USC!W6+UCLA!W6+Purdue!W6 -> 8 | X6: =Louisville!X6+SD!X6+ND!X6+Alabama!X6+UNO!X6+KSU!X6+Indiana!X6+Iowa!X6+Washington!X6+MSU!X6+Michigan!X6+Wisconsin!X6+Maryland!X6+Rutgers!X6+Illinois!X6+USC!X6+UCLA!X6+Purdue!X6 -> 15 | Y6: =IFERROR(X6/B6,0) -> 0.19480519 | Z6: =Louisville!Z6+SD!Z6+ND!Z6+Alabama!Z6+UNO!Z6+KSU!Z6+Indiana!Z6+Iowa!Z6+Washington!Z6+MSU!Z6+Michigan!Z6+Wisconsin!Z6+Maryland!Z6+Rutgers!Z6+Illinois!Z6+USC!Z6+UCLA!Z6+Purdue!Z6 -> 21 | AA6: =IFERROR(Z6/B6,0) -> 0.27272727 | AC6: ="<tr><td>Wistrom</td><td>"&B6&"</td><td>"&C6&"</td><td>"&D6&"</td><td>"&E6&"</td><td>"&F6&"</td><td>"&G6&"</td><td>"&H6&"</td><td>"&I6&"</td><td>"&J6&"</td><td>"&K6&"</td><td>"&L6&"</td><td>"&M6&"</td><td>"&N6&"</td><td>"&TEXT(O6,"0.00")&"</td><td>"&Z6&"</td><td>"&TEXT(AA6,"0.00")&"</td></tr>" -> <tr><td>Wistrom</td><td>77</td><td>0</td><td>0</td><td>0</td><td>0</td><td>0</td><td>2</td><td>2</td><td>1</td><td>1</td><td>0</td><td>0</td><td>6</td><td>0.08</td><td>21</td><td>0.27</td></tr> | AT6: ="<tr><td>Wistrom</td><td>"&B6&"</td><td>"&P6&"</td><td>"&Q6&"</td><td>"&R6&"</td><td>"&S6&"</td><td>"&T6&"</td><td>"&U6&"</td><td>"&V6&"</td><td>"&W6&"</td><td>"&X6&"</td><td>"&TEXT(Y6,"0.00")&"</td><td>"&Z6&"</td><td>"&TEXT(AA6,"0.00")&"</td></tr>" -> <tr><td>Wistrom</td><td>77</td><td>0</td><td>3</td><td>1</td><td>0</td><td>0</td><td>2</td><td>1</td><td>8</td><td>15</td><td>0.19</td><td>21</td><td>0.27</td></tr>
A7: dons | B7: =Louisville!B7+SD!B7+ND!B7+Alabama!B7+UNO!B7+KSU!B7+Indiana!B7+Iowa!B7+Washington!B7+MSU!B7+Michigan!B7+Wisconsin!B7+Maryland!B7+Rutgers!B7+Illinois!B7+USC!B7+UCLA!B7+Purdue!B7 -> 857 | C7: =Louisville!C7+SD!C7+ND!C7+Alabama!C7+UNO!C7+KSU!C7+Indiana!C7+Iowa!C7+Washington!C7+MSU!C7+Michigan!C7+Wisconsin!C7+Maryland!C7+Rutgers!C7+Illinois!C7+USC!C7+UCLA!C7+Purdue!C7 -> 1 | D7: =Louisville!D7+SD!D7+ND!D7+Alabama!D7+UNO!D7+KSU!D7+Indiana!D7+Iowa!D7+Washington!D7+MSU!D7+Michigan!D7+Wisconsin!D7+Maryland!D7+Rutgers!D7+Illinois!D7+USC!D7+UCLA!D7+Purdue!D7 -> 0 | E7: =Louisville!E7+SD!E7+ND!E7+Alabama!E7+UNO!E7+KSU!E7+Indiana!E7+Iowa!E7+Washington!E7+MSU!E7+Michigan!E7+Wisconsin!E7+Maryland!E7+Rutgers!E7+Illinois!E7+USC!E7+UCLA!E7+Purdue!E7 -> 4 | F7: =Louisville!F7+SD!F7+ND!F7+Alabama!F7+UNO!F7+KSU!F7+Indiana!F7+Iowa!F7+Washington!F7+MSU!F7+Michigan!F7+Wisconsin!F7+Maryland!F7+Rutgers!F7+Illinois!F7+USC!F7+UCLA!F7+Purdue!F7 -> 48 | G7: =Louisville!G7+SD!G7+ND!G7+Alabama!G7+UNO!G7+KSU!G7+Indiana!G7+Iowa!G7+Washington!G7+MSU!G7+Michigan!G7+Wisconsin!G7+Maryland!G7+Rutgers!G7+Illinois!G7+USC!G7+UCLA!G7+Purdue!G7 -> 0 | H7: =Louisville!H7+SD!H7+ND!H7+Alabama!H7+UNO!H7+KSU!H7+Indiana!H7+Iowa!H7+Washington!H7+MSU!H7+Michigan!H7+Wisconsin!H7+Maryland!H7+Rutgers!H7+Illinois!H7+USC!H7+UCLA!H7+Purdue!H7 -> 12 | I7: =Louisville!I7+SD!I7+ND!I7+Alabama!I7+UNO!I7+KSU!I7+Indiana!I7+Iowa!I7+Washington!I7+MSU!I7+Michigan!I7+Wisconsin!I7+Maryland!I7+Rutgers!I7+Illinois!I7+USC!I7+UCLA!I7+Purdue!I7 -> 18 | ... N7: =Louisville!N7+SD!N7+ND!N7+Alabama!N7+UNO!N7+KSU!N7+Indiana!N7+Iowa!N7+Washington!N7+MSU!N7+Michigan!N7+Wisconsin!N7+Maryland!N7+Rutgers!N7+Illinois!N7+USC!N7+UCLA!N7+Purdue!N7 -> 102 | O7: =IFERROR(N7/B7,0) -> 0.11901984 | P7: =Louisville!P7+SD!P7+ND!P7+Alabama!P7+UNO!P7+KSU!P7+Indiana!P7+Iowa!P7+Washington!P7+MSU!P7+Michigan!P7+Wisconsin!P7+Maryland!P7+Rutgers!P7+Illinois!P7+USC!P7+UCLA!P7+Purdue!P7 -> 30 | Q7: =Louisville!Q7+SD!Q7+ND!Q7+Alabama!Q7+UNO!Q7+KSU!Q7+Indiana!Q7+Iowa!Q7+Washington!Q7+MSU!Q7+Michigan!Q7+Wisconsin!Q7+Maryland!Q7+Rutgers!Q7+Illinois!Q7+USC!Q7+UCLA!Q7+Purdue!Q7 -> 46 | R7: =Louisville!R7+SD!R7+ND!R7+Alabama!R7+UNO!R7+KSU!R7+Indiana!R7+Iowa!R7+Washington!R7+MSU!R7+Michigan!R7+Wisconsin!R7+Maryland!R7+Rutgers!R7+Illinois!R7+USC!R7+UCLA!R7+Purdue!R7 -> 25 | S7: =Louisville!S7+SD!S7+ND!S7+Alabama!S7+UNO!S7+KSU!S7+Indiana!S7+Iowa!S7+Washington!S7+MSU!S7+Michigan!S7+Wisconsin!S7+Maryland!S7+Rutgers!S7+Illinois!S7+USC!S7+UCLA!S7+Purdue!S7 -> 17 | T7: =Louisville!T7+SD!T7+ND!T7+Alabama!T7+UNO!T7+KSU!T7+Indiana!T7+Iowa!T7+Washington!T7+MSU!T7+Michigan!T7+Wisconsin!T7+Maryland!T7+Rutgers!T7+Illinois!T7+USC!T7+UCLA!T7+Purdue!T7 -> 12 | U7: =Louisville!U7+SD!U7+ND!U7+Alabama!U7+UNO!U7+KSU!U7+Indiana!U7+Iowa!U7+Washington!U7+MSU!U7+Michigan!U7+Wisconsin!U7+Maryland!U7+Rutgers!U7+Illinois!U7+USC!U7+UCLA!U7+Purdue!U7 -> 5 | V7: =Louisville!V7+SD!V7+ND!V7+Alabama!V7+UNO!V7+KSU!V7+Indiana!V7+Iowa!V7+Washington!V7+MSU!V7+Michigan!V7+Wisconsin!V7+Maryland!V7+Rutgers!V7+Illinois!V7+USC!V7+UCLA!V7+Purdue!V7 -> 56 | W7: =Louisville!W7+SD!W7+ND!W7+Alabama!W7+UNO!W7+KSU!W7+Indiana!W7+Iowa!W7+Washington!W7+MSU!W7+Michigan!W7+Wisconsin!W7+Maryland!W7+Rutgers!W7+Illinois!W7+USC!W7+UCLA!W7+Purdue!W7 -> 41 | X7: =Louisville!X7+SD!X7+ND!X7+Alabama!X7+UNO!X7+KSU!X7+Indiana!X7+Iowa!X7+Washington!X7+MSU!X7+Michigan!X7+Wisconsin!X7+Maryland!X7+Rutgers!X7+Illinois!X7+USC!X7+UCLA!X7+Purdue!X7 -> 232 | Y7: =IFERROR(X7/B7,0) -> 0.27071179 | Z7: =Louisville!Z7+SD!Z7+ND!Z7+Alabama!Z7+UNO!Z7+KSU!Z7+Indiana!Z7+Iowa!Z7+Washington!Z7+MSU!Z7+Michigan!Z7+Wisconsin!Z7+Maryland!Z7+Rutgers!Z7+Illinois!Z7+USC!Z7+UCLA!Z7+Purdue!Z7 -> 334 | AA7: =IFERROR(Z7/B7,0) -> 0.38973162 | AC7: ="<tr><td>Donnelly</td><td>"&B7&"</td><td>"&C7&"</td><td>"&D7&"</td><td>"&E7&"</td><td>"&F7&"</td><td>"&G7&"</td><td>"&H7&"</td><td>"&I7&"</td><td>"&J7&"</td><td>"&K7&"</td><td>"&L7&"</td><td>"&M7&"</td><td>"&N7&"</td><td>"&TEXT(O7,"0.00")&"</td><td>"&Z7&"</td><td>"&TEXT(AA7,"0.00")&"</td></tr>" -> <tr><td>Donnelly</td><td>857</td><td>1</td><td>0</td><td>4</td><td>48</td><td>0</td><td>12</td><td>18</td><td>4</td><td>5</td><td>8</td><td>2</td><td>102</td><td>0.12</td><td>334</td><td>0.39</td></tr> | AT7: ="<tr><td>Donnelly</td><td>"&B7&"</td><td>"&P7&"</td><td>"&Q7&"</td><td>"&R7&"</td><td>"&S7&"</td><td>"&T7&"</td><td>"&U7&"</td><td>"&V7&"</td><td>"&W7&"</td><td>"&X7&"</td><td>"&TEXT(Y7,"0.00")&"</td><td>"&Z7&"</td><td>"&TEXT(AA7,"0.00")&"</td></tr>" -> <tr><td>Donnelly</td><td>857</td><td>30</td><td>46</td><td>25</td><td>17</td><td>12</td><td>5</td><td>56</td><td>41</td><td>232</td><td>0.27</td><td>334</td><td>0.39</td></tr>
A8: droz | B8: =Louisville!B8+SD!B8+ND!B8+Alabama!B8+UNO!B8+KSU!B8+Indiana!B8+Iowa!B8+Washington!B8+MSU!B8+Michigan!B8+Wisconsin!B8+Maryland!B8+Rutgers!B8+Illinois!B8+USC!B8+UCLA!B8+Purdue!B8 -> 84 | C8: =Louisville!C8+SD!C8+ND!C8+Alabama!C8+UNO!C8+KSU!C8+Indiana!C8+Iowa!C8+Washington!C8+MSU!C8+Michigan!C8+Wisconsin!C8+Maryland!C8+Rutgers!C8+Illinois!C8+USC!C8+UCLA!C8+Purdue!C8 -> 0 | D8: =Louisville!D8+SD!D8+ND!D8+Alabama!D8+UNO!D8+KSU!D8+Indiana!D8+Iowa!D8+Washington!D8+MSU!D8+Michigan!D8+Wisconsin!D8+Maryland!D8+Rutgers!D8+Illinois!D8+USC!D8+UCLA!D8+Purdue!D8 -> 0 | E8: =Louisville!E8+SD!E8+ND!E8+Alabama!E8+UNO!E8+KSU!E8+Indiana!E8+Iowa!E8+Washington!E8+MSU!E8+Michigan!E8+Wisconsin!E8+Maryland!E8+Rutgers!E8+Illinois!E8+USC!E8+UCLA!E8+Purdue!E8 -> 1 | F8: =Louisville!F8+SD!F8+ND!F8+Alabama!F8+UNO!F8+KSU!F8+Indiana!F8+Iowa!F8+Washington!F8+MSU!F8+Michigan!F8+Wisconsin!F8+Maryland!F8+Rutgers!F8+Illinois!F8+USC!F8+UCLA!F8+Purdue!F8 -> 3 | G8: =Louisville!G8+SD!G8+ND!G8+Alabama!G8+UNO!G8+KSU!G8+Indiana!G8+Iowa!G8+Washington!G8+MSU!G8+Michigan!G8+Wisconsin!G8+Maryland!G8+Rutgers!G8+Illinois!G8+USC!G8+UCLA!G8+Purdue!G8 -> 1 | H8: =Louisville!H8+SD!H8+ND!H8+Alabama!H8+UNO!H8+KSU!H8+Indiana!H8+Iowa!H8+Washington!H8+MSU!H8+Michigan!H8+Wisconsin!H8+Maryland!H8+Rutgers!H8+Illinois!H8+USC!H8+UCLA!H8+Purdue!H8 -> 1 | I8: =Louisville!I8+SD!I8+ND!I8+Alabama!I8+UNO!I8+KSU!I8+Indiana!I8+Iowa!I8+Washington!I8+MSU!I8+Michigan!I8+Wisconsin!I8+Maryland!I8+Rutgers!I8+Illinois!I8+USC!I8+UCLA!I8+Purdue!I8 -> 2 | ... N8: =Louisville!N8+SD!N8+ND!N8+Alabama!N8+UNO!N8+KSU!N8+Indiana!N8+Iowa!N8+Washington!N8+MSU!N8+Michigan!N8+Wisconsin!N8+Maryland!N8+Rutgers!N8+Illinois!N8+USC!N8+UCLA!N8+Purdue!N8 -> 13 | O8: =IFERROR(N8/B8,0) -> 0.1547619 | P8: =Louisville!P8+SD!P8+ND!P8+Alabama!P8+UNO!P8+KSU!P8+Indiana!P8+Iowa!P8+Washington!P8+MSU!P8+Michigan!P8+Wisconsin!P8+Maryland!P8+Rutgers!P8+Illinois!P8+USC!P8+UCLA!P8+Purdue!P8 -> 3 | Q8: =Louisville!Q8+SD!Q8+ND!Q8+Alabama!Q8+UNO!Q8+KSU!Q8+Indiana!Q8+Iowa!Q8+Washington!Q8+MSU!Q8+Michigan!Q8+Wisconsin!Q8+Maryland!Q8+Rutgers!Q8+Illinois!Q8+USC!Q8+UCLA!Q8+Purdue!Q8 -> 2 | R8: =Louisville!R8+SD!R8+ND!R8+Alabama!R8+UNO!R8+KSU!R8+Indiana!R8+Iowa!R8+Washington!R8+MSU!R8+Michigan!R8+Wisconsin!R8+Maryland!R8+Rutgers!R8+Illinois!R8+USC!R8+UCLA!R8+Purdue!R8 -> 3 | S8: =Louisville!S8+SD!S8+ND!S8+Alabama!S8+UNO!S8+KSU!S8+Indiana!S8+Iowa!S8+Washington!S8+MSU!S8+Michigan!S8+Wisconsin!S8+Maryland!S8+Rutgers!S8+Illinois!S8+USC!S8+UCLA!S8+Purdue!S8 -> 1 | T8: =Louisville!T8+SD!T8+ND!T8+Alabama!T8+UNO!T8+KSU!T8+Indiana!T8+Iowa!T8+Washington!T8+MSU!T8+Michigan!T8+Wisconsin!T8+Maryland!T8+Rutgers!T8+Illinois!T8+USC!T8+UCLA!T8+Purdue!T8 -> 0 | U8: =Louisville!U8+SD!U8+ND!U8+Alabama!U8+UNO!U8+KSU!U8+Indiana!U8+Iowa!U8+Washington!U8+MSU!U8+Michigan!U8+Wisconsin!U8+Maryland!U8+Rutgers!U8+Illinois!U8+USC!U8+UCLA!U8+Purdue!U8 -> 0 | V8: =Louisville!V8+SD!V8+ND!V8+Alabama!V8+UNO!V8+KSU!V8+Indiana!V8+Iowa!V8+Washington!V8+MSU!V8+Michigan!V8+Wisconsin!V8+Maryland!V8+Rutgers!V8+Illinois!V8+USC!V8+UCLA!V8+Purdue!V8 -> 2 | W8: =Louisville!W8+SD!W8+ND!W8+Alabama!W8+UNO!W8+KSU!W8+Indiana!W8+Iowa!W8+Washington!W8+MSU!W8+Michigan!W8+Wisconsin!W8+Maryland!W8+Rutgers!W8+Illinois!W8+USC!W8+UCLA!W8+Purdue!W8 -> 6 | X8: =Louisville!X8+SD!X8+ND!X8+Alabama!X8+UNO!X8+KSU!X8+Indiana!X8+Iowa!X8+Washington!X8+MSU!X8+Michigan!X8+Wisconsin!X8+Maryland!X8+Rutgers!X8+Illinois!X8+USC!X8+UCLA!X8+Purdue!X8 -> 17 | Y8: =IFERROR(X8/B8,0) -> 0.20238095 | Z8: =Louisville!Z8+SD!Z8+ND!Z8+Alabama!Z8+UNO!Z8+KSU!Z8+Indiana!Z8+Iowa!Z8+Washington!Z8+MSU!Z8+Michigan!Z8+Wisconsin!Z8+Maryland!Z8+Rutgers!Z8+Illinois!Z8+USC!Z8+UCLA!Z8+Purdue!Z8 -> 30 | AA8: =IFERROR(Z8/B8,0) -> 0.35714286 | AC8: ="<tr><td>Drozda</td><td>"&B8&"</td><td>"&C8&"</td><td>"&D8&"</td><td>"&E8&"</td><td>"&F8&"</td><td>"&G8&"</td><td>"&H8&"</td><td>"&I8&"</td><td>"&J8&"</td><td>"&K8&"</td><td>"&L8&"</td><td>"&M8&"</td><td>"&N8&"</td><td>"&TEXT(O8,"0.00")&"</td><td>"&Z8&"</td><td>"&TEXT(AA8,"0.00")&"</td></tr>" -> <tr><td>Drozda</td><td>84</td><td>0</td><td>0</td><td>1</td><td>3</td><td>1</td><td>1</td><td>2</td><td>0</td><td>2</td><td>2</td><td>1</td><td>13</td><td>0.15</td><td>30</td><td>0.36</td></tr> | AT8: ="<tr><td>Drozda</td><td>"&B8&"</td><td>"&P8&"</td><td>"&Q8&"</td><td>"&R8&"</td><td>"&S8&"</td><td>"&T8&"</td><td>"&U8&"</td><td>"&V8&"</td><td>"&W8&"</td><td>"&X8&"</td><td>"&TEXT(Y8,"0.00")&"</td><td>"&Z8&"</td><td>"&TEXT(AA8,"0.00")&"</td></tr>" -> <tr><td>Drozda</td><td>84</td><td>3</td><td>2</td><td>3</td><td>1</td><td>0</td><td>0</td><td>2</td><td>6</td><td>17</td><td>0.20</td><td>30</td><td>0.36</td></tr>
A9: ella g | B9: =Louisville!B9+SD!B9+ND!B9+Alabama!B9+UNO!B9+KSU!B9+Indiana!B9+Iowa!B9+Washington!B9+MSU!B9+Michigan!B9+Wisconsin!B9+Maryland!B9+Rutgers!B9+Illinois!B9+USC!B9+UCLA!B9+Purdue!B9 -> 338 | C9: =Louisville!C9+SD!C9+ND!C9+Alabama!C9+UNO!C9+KSU!C9+Indiana!C9+Iowa!C9+Washington!C9+MSU!C9+Michigan!C9+Wisconsin!C9+Maryland!C9+Rutgers!C9+Illinois!C9+USC!C9+UCLA!C9+Purdue!C9 -> 1 | D9: =Louisville!D9+SD!D9+ND!D9+Alabama!D9+UNO!D9+KSU!D9+Indiana!D9+Iowa!D9+Washington!D9+MSU!D9+Michigan!D9+Wisconsin!D9+Maryland!D9+Rutgers!D9+Illinois!D9+USC!D9+UCLA!D9+Purdue!D9 -> 1 | E9: =Louisville!E9+SD!E9+ND!E9+Alabama!E9+UNO!E9+KSU!E9+Indiana!E9+Iowa!E9+Washington!E9+MSU!E9+Michigan!E9+Wisconsin!E9+Maryland!E9+Rutgers!E9+Illinois!E9+USC!E9+UCLA!E9+Purdue!E9 -> 1 | F9: =Louisville!F9+SD!F9+ND!F9+Alabama!F9+UNO!F9+KSU!F9+Indiana!F9+Iowa!F9+Washington!F9+MSU!F9+Michigan!F9+Wisconsin!F9+Maryland!F9+Rutgers!F9+Illinois!F9+USC!F9+UCLA!F9+Purdue!F9 -> 20 | G9: =Louisville!G9+SD!G9+ND!G9+Alabama!G9+UNO!G9+KSU!G9+Indiana!G9+Iowa!G9+Washington!G9+MSU!G9+Michigan!G9+Wisconsin!G9+Maryland!G9+Rutgers!G9+Illinois!G9+USC!G9+UCLA!G9+Purdue!G9 -> 0 | H9: =Louisville!H9+SD!H9+ND!H9+Alabama!H9+UNO!H9+KSU!H9+Indiana!H9+Iowa!H9+Washington!H9+MSU!H9+Michigan!H9+Wisconsin!H9+Maryland!H9+Rutgers!H9+Illinois!H9+USC!H9+UCLA!H9+Purdue!H9 -> 3 | I9: =Louisville!I9+SD!I9+ND!I9+Alabama!I9+UNO!I9+KSU!I9+Indiana!I9+Iowa!I9+Washington!I9+MSU!I9+Michigan!I9+Wisconsin!I9+Maryland!I9+Rutgers!I9+Illinois!I9+USC!I9+UCLA!I9+Purdue!I9 -> 12 | ... N9: =Louisville!N9+SD!N9+ND!N9+Alabama!N9+UNO!N9+KSU!N9+Indiana!N9+Iowa!N9+Washington!N9+MSU!N9+Michigan!N9+Wisconsin!N9+Maryland!N9+Rutgers!N9+Illinois!N9+USC!N9+UCLA!N9+Purdue!N9 -> 57 | O9: =IFERROR(N9/B9,0) -> 0.16863905 | P9: =Louisville!P9+SD!P9+ND!P9+Alabama!P9+UNO!P9+KSU!P9+Indiana!P9+Iowa!P9+Washington!P9+MSU!P9+Michigan!P9+Wisconsin!P9+Maryland!P9+Rutgers!P9+Illinois!P9+USC!P9+UCLA!P9+Purdue!P9 -> 4 | Q9: =Louisville!Q9+SD!Q9+ND!Q9+Alabama!Q9+UNO!Q9+KSU!Q9+Indiana!Q9+Iowa!Q9+Washington!Q9+MSU!Q9+Michigan!Q9+Wisconsin!Q9+Maryland!Q9+Rutgers!Q9+Illinois!Q9+USC!Q9+UCLA!Q9+Purdue!Q9 -> 21 | R9: =Louisville!R9+SD!R9+ND!R9+Alabama!R9+UNO!R9+KSU!R9+Indiana!R9+Iowa!R9+Washington!R9+MSU!R9+Michigan!R9+Wisconsin!R9+Maryland!R9+Rutgers!R9+Illinois!R9+USC!R9+UCLA!R9+Purdue!R9 -> 10 | S9: =Louisville!S9+SD!S9+ND!S9+Alabama!S9+UNO!S9+KSU!S9+Indiana!S9+Iowa!S9+Washington!S9+MSU!S9+Michigan!S9+Wisconsin!S9+Maryland!S9+Rutgers!S9+Illinois!S9+USC!S9+UCLA!S9+Purdue!S9 -> 0 | T9: =Louisville!T9+SD!T9+ND!T9+Alabama!T9+UNO!T9+KSU!T9+Indiana!T9+Iowa!T9+Washington!T9+MSU!T9+Michigan!T9+Wisconsin!T9+Maryland!T9+Rutgers!T9+Illinois!T9+USC!T9+UCLA!T9+Purdue!T9 -> 4 | U9: =Louisville!U9+SD!U9+ND!U9+Alabama!U9+UNO!U9+KSU!U9+Indiana!U9+Iowa!U9+Washington!U9+MSU!U9+Michigan!U9+Wisconsin!U9+Maryland!U9+Rutgers!U9+Illinois!U9+USC!U9+UCLA!U9+Purdue!U9 -> 5 | V9: =Louisville!V9+SD!V9+ND!V9+Alabama!V9+UNO!V9+KSU!V9+Indiana!V9+Iowa!V9+Washington!V9+MSU!V9+Michigan!V9+Wisconsin!V9+Maryland!V9+Rutgers!V9+Illinois!V9+USC!V9+UCLA!V9+Purdue!V9 -> 19 | W9: =Louisville!W9+SD!W9+ND!W9+Alabama!W9+UNO!W9+KSU!W9+Indiana!W9+Iowa!W9+Washington!W9+MSU!W9+Michigan!W9+Wisconsin!W9+Maryland!W9+Rutgers!W9+Illinois!W9+USC!W9+UCLA!W9+Purdue!W9 -> 17 | X9: =Louisville!X9+SD!X9+ND!X9+Alabama!X9+UNO!X9+KSU!X9+Indiana!X9+Iowa!X9+Washington!X9+MSU!X9+Michigan!X9+Wisconsin!X9+Maryland!X9+Rutgers!X9+Illinois!X9+USC!X9+UCLA!X9+Purdue!X9 -> 80 | Y9: =IFERROR(X9/B9,0) -> 0.23668639 | Z9: =Louisville!Z9+SD!Z9+ND!Z9+Alabama!Z9+UNO!Z9+KSU!Z9+Indiana!Z9+Iowa!Z9+Washington!Z9+MSU!Z9+Michigan!Z9+Wisconsin!Z9+Maryland!Z9+Rutgers!Z9+Illinois!Z9+USC!Z9+UCLA!Z9+Purdue!Z9 -> 137 | AA9: =IFERROR(Z9/B9,0) -> 0.40532544 | AC9: ="<tr><td>Guyott</td><td>"&B9&"</td><td>"&C9&"</td><td>"&D9&"</td><td>"&E9&"</td><td>"&F9&"</td><td>"&G9&"</td><td>"&H9&"</td><td>"&I9&"</td><td>"&J9&"</td><td>"&K9&"</td><td>"&L9&"</td><td>"&M9&"</td><td>"&N9&"</td><td>"&TEXT(O9,"0.00")&"</td><td>"&Z9&"</td><td>"&TEXT(AA9,"0.00")&"</td></tr>" -> <tr><td>Guyott</td><td>338</td><td>1</td><td>1</td><td>1</td><td>20</td><td>0</td><td>3</td><td>12</td><td>3</td><td>13</td><td>1</td><td>2</td><td>57</td><td>0.17</td><td>137</td><td>0.41</td></tr> | AT9: ="<tr><td>Guyott</td><td>"&B9&"</td><td>"&P9&"</td><td>"&Q9&"</td><td>"&R9&"</td><td>"&S9&"</td><td>"&T9&"</td><td>"&U9&"</td><td>"&V9&"</td><td>"&W9&"</td><td>"&X9&"</td><td>"&TEXT(Y9,"0.00")&"</td><td>"&Z9&"</td><td>"&TEXT(AA9,"0.00")&"</td></tr>" -> <tr><td>Guyott</td><td>338</td><td>4</td><td>21</td><td>10</td><td>0</td><td>4</td><td>5</td><td>19</td><td>17</td><td>80</td><td>0.24</td><td>137</td><td>0.41</td></tr>
A10: ella r | B10: =Louisville!B10+SD!B10+ND!B10+Alabama!B10+UNO!B10+KSU!B10+Indiana!B10+Iowa!B10+Washington!B10+MSU!B10+Michigan!B10+Wisconsin!B10+Maryland!B10+Rutgers!B10+Illinois!B10+USC!B10+UCLA!B10+Purdue!B10 -> 751 | C10: =Louisville!C10+SD!C10+ND!C10+Alabama!C10+UNO!C10+KSU!C10+Indiana!C10+Iowa!C10+Washington!C10+MSU!C10+Michigan!C10+Wisconsin!C10+Maryland!C10+Rutgers!C10+Illinois!C10+USC!C10+UCLA!C10+Purdue!C10 -> 1 | D10: =Louisville!D10+SD!D10+ND!D10+Alabama!D10+UNO!D10+KSU!D10+Indiana!D10+Iowa!D10+Washington!D10+MSU!D10+Michigan!D10+Wisconsin!D10+Maryland!D10+Rutgers!D10+Illinois!D10+USC!D10+UCLA!D10+Purdue!D10 -> 2 | E10: =Louisville!E10+SD!E10+ND!E10+Alabama!E10+UNO!E10+KSU!E10+Indiana!E10+Iowa!E10+Washington!E10+MSU!E10+Michigan!E10+Wisconsin!E10+Maryland!E10+Rutgers!E10+Illinois!E10+USC!E10+UCLA!E10+Purdue!E10 -> 6 | F10: =Louisville!F10+SD!F10+ND!F10+Alabama!F10+UNO!F10+KSU!F10+Indiana!F10+Iowa!F10+Washington!F10+MSU!F10+Michigan!F10+Wisconsin!F10+Maryland!F10+Rutgers!F10+Illinois!F10+USC!F10+UCLA!F10+Purdue!F10 -> 17 | G10: =Louisville!G10+SD!G10+ND!G10+Alabama!G10+UNO!G10+KSU!G10+Indiana!G10+Iowa!G10+Washington!G10+MSU!G10+Michigan!G10+Wisconsin!G10+Maryland!G10+Rutgers!G10+Illinois!G10+USC!G10+UCLA!G10+Purdue!G10 -> 7 | H10: =Louisville!H10+SD!H10+ND!H10+Alabama!H10+UNO!H10+KSU!H10+Indiana!H10+Iowa!H10+Washington!H10+MSU!H10+Michigan!H10+Wisconsin!H10+Maryland!H10+Rutgers!H10+Illinois!H10+USC!H10+UCLA!H10+Purdue!H10 -> 5 | I10: =Louisville!I10+SD!I10+ND!I10+Alabama!I10+UNO!I10+KSU!I10+Indiana!I10+Iowa!I10+Washington!I10+MSU!I10+Michigan!I10+Wisconsin!I10+Maryland!I10+Rutgers!I10+Illinois!I10+USC!I10+UCLA!I10+Purdue!I10 -> 10 | ... N10: =Louisville!N10+SD!N10+ND!N10+Alabama!N10+UNO!N10+KSU!N10+Indiana!N10+Iowa!N10+Washington!N10+MSU!N10+Michigan!N10+Wisconsin!N10+Maryland!N10+Rutgers!N10+Illinois!N10+USC!N10+UCLA!N10+Purdue!N10 -> 96 | O10: =IFERROR(N10/B10,0) -> 0.12782956 | P10: =Louisville!P10+SD!P10+ND!P10+Alabama!P10+UNO!P10+KSU!P10+Indiana!P10+Iowa!P10+Washington!P10+MSU!P10+Michigan!P10+Wisconsin!P10+Maryland!P10+Rutgers!P10+Illinois!P10+USC!P10+UCLA!P10+Purdue!P10 -> 15 | Q10: =Louisville!Q10+SD!Q10+ND!Q10+Alabama!Q10+UNO!Q10+KSU!Q10+Indiana!Q10+Iowa!Q10+Washington!Q10+MSU!Q10+Michigan!Q10+Wisconsin!Q10+Maryland!Q10+Rutgers!Q10+Illinois!Q10+USC!Q10+UCLA!Q10+Purdue!Q10 -> 13 | R10: =Louisville!R10+SD!R10+ND!R10+Alabama!R10+UNO!R10+KSU!R10+Indiana!R10+Iowa!R10+Washington!R10+MSU!R10+Michigan!R10+Wisconsin!R10+Maryland!R10+Rutgers!R10+Illinois!R10+USC!R10+UCLA!R10+Purdue!R10 -> 18 | S10: =Louisville!S10+SD!S10+ND!S10+Alabama!S10+UNO!S10+KSU!S10+Indiana!S10+Iowa!S10+Washington!S10+MSU!S10+Michigan!S10+Wisconsin!S10+Maryland!S10+Rutgers!S10+Illinois!S10+USC!S10+UCLA!S10+Purdue!S10 -> 1 | T10: =Louisville!T10+SD!T10+ND!T10+Alabama!T10+UNO!T10+KSU!T10+Indiana!T10+Iowa!T10+Washington!T10+MSU!T10+Michigan!T10+Wisconsin!T10+Maryland!T10+Rutgers!T10+Illinois!T10+USC!T10+UCLA!T10+Purdue!T10 -> 6 | U10: =Louisville!U10+SD!U10+ND!U10+Alabama!U10+UNO!U10+KSU!U10+Indiana!U10+Iowa!U10+Washington!U10+MSU!U10+Michigan!U10+Wisconsin!U10+Maryland!U10+Rutgers!U10+Illinois!U10+USC!U10+UCLA!U10+Purdue!U10 -> 4 | V10: =Louisville!V10+SD!V10+ND!V10+Alabama!V10+UNO!V10+KSU!V10+Indiana!V10+Iowa!V10+Washington!V10+MSU!V10+Michigan!V10+Wisconsin!V10+Maryland!V10+Rutgers!V10+Illinois!V10+USC!V10+UCLA!V10+Purdue!V10 -> 2 | W10: =Louisville!W10+SD!W10+ND!W10+Alabama!W10+UNO!W10+KSU!W10+Indiana!W10+Iowa!W10+Washington!W10+MSU!W10+Michigan!W10+Wisconsin!W10+Maryland!W10+Rutgers!W10+Illinois!W10+USC!W10+UCLA!W10+Purdue!W10 -> 20 | X10: =Louisville!X10+SD!X10+ND!X10+Alabama!X10+UNO!X10+KSU!X10+Indiana!X10+Iowa!X10+Washington!X10+MSU!X10+Michigan!X10+Wisconsin!X10+Maryland!X10+Rutgers!X10+Illinois!X10+USC!X10+UCLA!X10+Purdue!X10 -> 79 | Y10: =IFERROR(X10/B10,0) -> 0.10519308 | Z10: =Louisville!Z10+SD!Z10+ND!Z10+Alabama!Z10+UNO!Z10+KSU!Z10+Indiana!Z10+Iowa!Z10+Washington!Z10+MSU!Z10+Michigan!Z10+Wisconsin!Z10+Maryland!Z10+Rutgers!Z10+Illinois!Z10+USC!Z10+UCLA!Z10+Purdue!Z10 -> 175 | AA10: =IFERROR(Z10/B10,0) -> 0.23302264 | AC10: ="<tr><td>Rudney</td><td>"&B10&"</td><td>"&C10&"</td><td>"&D10&"</td><td>"&E10&"</td><td>"&F10&"</td><td>"&G10&"</td><td>"&H10&"</td><td>"&I10&"</td><td>"&J10&"</td><td>"&K10&"</td><td>"&L10&"</td><td>"&M10&"</td><td>"&N10&"</td><td>"&TEXT(O10,"0.00")&"</td><td>"&Z10&"</td><td>"&TEXT(AA10,"0.00")&"</td></tr>" -> <tr><td>Rudney</td><td>751</td><td>1</td><td>2</td><td>6</td><td>17</td><td>7</td><td>5</td><td>10</td><td>13</td><td>14</td><td>19</td><td>9</td><td>96</td><td>0.13</td><td>175</td><td>0.23</td></tr> | AT10: ="<tr><td>Rudney</td><td>"&B10&"</td><td>"&P10&"</td><td>"&Q10&"</td><td>"&R10&"</td><td>"&S10&"</td><td>"&T10&"</td><td>"&U10&"</td><td>"&V10&"</td><td>"&W10&"</td><td>"&X10&"</td><td>"&TEXT(Y10,"0.00")&"</td><td>"&Z10&"</td><td>"&TEXT(AA10,"0.00")&"</td></tr>" -> <tr><td>Rudney</td><td>751</td><td>15</td><td>13</td><td>18</td><td>1</td><td>6</td><td>4</td><td>2</td><td>20</td><td>79</td><td>0.11</td><td>175</td><td>0.23</td></tr>
A11: emma p | B11: =Louisville!B11+SD!B11+ND!B11+Alabama!B11+UNO!B11+KSU!B11+Indiana!B11+Iowa!B11+Washington!B11+MSU!B11+Michigan!B11+Wisconsin!B11+Maryland!B11+Rutgers!B11+Illinois!B11+USC!B11+UCLA!B11+Purdue!B11 -> 38 | C11: =Louisville!C11+SD!C11+ND!C11+Alabama!C11+UNO!C11+KSU!C11+Indiana!C11+Iowa!C11+Washington!C11+MSU!C11+Michigan!C11+Wisconsin!C11+Maryland!C11+Rutgers!C11+Illinois!C11+USC!C11+UCLA!C11+Purdue!C11 -> 0 | D11: =Louisville!D11+SD!D11+ND!D11+Alabama!D11+UNO!D11+KSU!D11+Indiana!D11+Iowa!D11+Washington!D11+MSU!D11+Michigan!D11+Wisconsin!D11+Maryland!D11+Rutgers!D11+Illinois!D11+USC!D11+UCLA!D11+Purdue!D11 -> 0 | E11: =Louisville!E11+SD!E11+ND!E11+Alabama!E11+UNO!E11+KSU!E11+Indiana!E11+Iowa!E11+Washington!E11+MSU!E11+Michigan!E11+Wisconsin!E11+Maryland!E11+Rutgers!E11+Illinois!E11+USC!E11+UCLA!E11+Purdue!E11 -> 0 | F11: =Louisville!F11+SD!F11+ND!F11+Alabama!F11+UNO!F11+KSU!F11+Indiana!F11+Iowa!F11+Washington!F11+MSU!F11+Michigan!F11+Wisconsin!F11+Maryland!F11+Rutgers!F11+Illinois!F11+USC!F11+UCLA!F11+Purdue!F11 -> 0 | G11: =Louisville!G11+SD!G11+ND!G11+Alabama!G11+UNO!G11+KSU!G11+Indiana!G11+Iowa!G11+Washington!G11+MSU!G11+Michigan!G11+Wisconsin!G11+Maryland!G11+Rutgers!G11+Illinois!G11+USC!G11+UCLA!G11+Purdue!G11 -> 0 | H11: =Louisville!H11+SD!H11+ND!H11+Alabama!H11+UNO!H11+KSU!H11+Indiana!H11+Iowa!H11+Washington!H11+MSU!H11+Michigan!H11+Wisconsin!H11+Maryland!H11+Rutgers!H11+Illinois!H11+USC!H11+UCLA!H11+Purdue!H11 -> 0 | I11: =Louisville!I11+SD!I11+ND!I11+Alabama!I11+UNO!I11+KSU!I11+Indiana!I11+Iowa!I11+Washington!I11+MSU!I11+Michigan!I11+Wisconsin!I11+Maryland!I11+Rutgers!I11+Illinois!I11+USC!I11+UCLA!I11+Purdue!I11 -> 0 | ... N11: =Louisville!N11+SD!N11+ND!N11+Alabama!N11+UNO!N11+KSU!N11+Indiana!N11+Iowa!N11+Washington!N11+MSU!N11+Michigan!N11+Wisconsin!N11+Maryland!N11+Rutgers!N11+Illinois!N11+USC!N11+UCLA!N11+Purdue!N11 -> 2 | O11: =IFERROR(N11/B11,0) -> 0.052631579 | P11: =Louisville!P11+SD!P11+ND!P11+Alabama!P11+UNO!P11+KSU!P11+Indiana!P11+Iowa!P11+Washington!P11+MSU!P11+Michigan!P11+Wisconsin!P11+Maryland!P11+Rutgers!P11+Illinois!P11+USC!P11+UCLA!P11+Purdue!P11 -> 1 | Q11: =Louisville!Q11+SD!Q11+ND!Q11+Alabama!Q11+UNO!Q11+KSU!Q11+Indiana!Q11+Iowa!Q11+Washington!Q11+MSU!Q11+Michigan!Q11+Wisconsin!Q11+Maryland!Q11+Rutgers!Q11+Illinois!Q11+USC!Q11+UCLA!Q11+Purdue!Q11 -> 0 | R11: =Louisville!R11+SD!R11+ND!R11+Alabama!R11+UNO!R11+KSU!R11+Indiana!R11+Iowa!R11+Washington!R11+MSU!R11+Michigan!R11+Wisconsin!R11+Maryland!R11+Rutgers!R11+Illinois!R11+USC!R11+UCLA!R11+Purdue!R11 -> 0 | S11: =Louisville!S11+SD!S11+ND!S11+Alabama!S11+UNO!S11+KSU!S11+Indiana!S11+Iowa!S11+Washington!S11+MSU!S11+Michigan!S11+Wisconsin!S11+Maryland!S11+Rutgers!S11+Illinois!S11+USC!S11+UCLA!S11+Purdue!S11 -> 0 | T11: =Louisville!T11+SD!T11+ND!T11+Alabama!T11+UNO!T11+KSU!T11+Indiana!T11+Iowa!T11+Washington!T11+MSU!T11+Michigan!T11+Wisconsin!T11+Maryland!T11+Rutgers!T11+Illinois!T11+USC!T11+UCLA!T11+Purdue!T11 -> 1 | U11: =Louisville!U11+SD!U11+ND!U11+Alabama!U11+UNO!U11+KSU!U11+Indiana!U11+Iowa!U11+Washington!U11+MSU!U11+Michigan!U11+Wisconsin!U11+Maryland!U11+Rutgers!U11+Illinois!U11+USC!U11+UCLA!U11+Purdue!U11 -> 0 | V11: =Louisville!V11+SD!V11+ND!V11+Alabama!V11+UNO!V11+KSU!V11+Indiana!V11+Iowa!V11+Washington!V11+MSU!V11+Michigan!V11+Wisconsin!V11+Maryland!V11+Rutgers!V11+Illinois!V11+USC!V11+UCLA!V11+Purdue!V11 -> 1 | W11: =Louisville!W11+SD!W11+ND!W11+Alabama!W11+UNO!W11+KSU!W11+Indiana!W11+Iowa!W11+Washington!W11+MSU!W11+Michigan!W11+Wisconsin!W11+Maryland!W11+Rutgers!W11+Illinois!W11+USC!W11+UCLA!W11+Purdue!W11 -> 4 | X11: =Louisville!X11+SD!X11+ND!X11+Alabama!X11+UNO!X11+KSU!X11+Indiana!X11+Iowa!X11+Washington!X11+MSU!X11+Michigan!X11+Wisconsin!X11+Maryland!X11+Rutgers!X11+Illinois!X11+USC!X11+UCLA!X11+Purdue!X11 -> 7 | Y11: =IFERROR(X11/B11,0) -> 0.18421053 | Z11: =Louisville!Z11+SD!Z11+ND!Z11+Alabama!Z11+UNO!Z11+KSU!Z11+Indiana!Z11+Iowa!Z11+Washington!Z11+MSU!Z11+Michigan!Z11+Wisconsin!Z11+Maryland!Z11+Rutgers!Z11+Illinois!Z11+USC!Z11+UCLA!Z11+Purdue!Z11 -> 9 | AA11: =IFERROR(Z11/B11,0) -> 0.23684211 | AC11: ="<tr><td>Prososki</td><td>"&B11&"</td><td>"&C11&"</td><td>"&D11&"</td><td>"&E11&"</td><td>"&F11&"</td><td>"&G11&"</td><td>"&H11&"</td><td>"&I11&"</td><td>"&J11&"</td><td>"&K11&"</td><td>"&L11&"</td><td>"&M11&"</td><td>"&N11&"</td><td>"&TEXT(O11,"0.00")&"</td><td>"&Z11&"</td><td>"&TEXT(AA11,"0.00")&"</td></tr>" -> <tr><td>Prososki</td><td>38</td><td>0</td><td>0</td><td>0</td><td>0</td><td>0</td><td>0</td><td>0</td><td>2</td><td>0</td><td>0</td><td>0</td><td>2</td><td>0.05</td><td>9</td><td>0.24</td></tr> | AT11: ="<tr><td>Prososki</td><td>"&B11&"</td><td>"&P11&"</td><td>"&Q11&"</td><td>"&R11&"</td><td>"&S11&"</td><td>"&T11&"</td><td>"&U11&"</td><td>"&V11&"</td><td>"&W11&"</td><td>"&X11&"</td><td>"&TEXT(Y11,"0.00")&"</td><td>"&Z11&"</td><td>"&TEXT(AA11,"0.00")&"</td></tr>" -> <tr><td>Prososki</td><td>38</td><td>1</td><td>0</td><td>0</td><td>0</td><td>1</td><td>0</td><td>1</td><td>4</td><td>7</td><td>0.18</td><td>9</td><td>0.24</td></tr>
A12: emma r | B12: =Louisville!B12+SD!B12+ND!B12+Alabama!B12+UNO!B12+KSU!B12+Indiana!B12+Iowa!B12+Washington!B12+MSU!B12+Michigan!B12+Wisconsin!B12+Maryland!B12+Rutgers!B12+Illinois!B12+USC!B12+UCLA!B12+Purdue!B12 -> 342 | C12: =Louisville!C12+SD!C12+ND!C12+Alabama!C12+UNO!C12+KSU!C12+Indiana!C12+Iowa!C12+Washington!C12+MSU!C12+Michigan!C12+Wisconsin!C12+Maryland!C12+Rutgers!C12+Illinois!C12+USC!C12+UCLA!C12+Purdue!C12 -> 0 | D12: =Louisville!D12+SD!D12+ND!D12+Alabama!D12+UNO!D12+KSU!D12+Indiana!D12+Iowa!D12+Washington!D12+MSU!D12+Michigan!D12+Wisconsin!D12+Maryland!D12+Rutgers!D12+Illinois!D12+USC!D12+UCLA!D12+Purdue!D12 -> 0 | E12: =Louisville!E12+SD!E12+ND!E12+Alabama!E12+UNO!E12+KSU!E12+Indiana!E12+Iowa!E12+Washington!E12+MSU!E12+Michigan!E12+Wisconsin!E12+Maryland!E12+Rutgers!E12+Illinois!E12+USC!E12+UCLA!E12+Purdue!E12 -> 0 | F12: =Louisville!F12+SD!F12+ND!F12+Alabama!F12+UNO!F12+KSU!F12+Indiana!F12+Iowa!F12+Washington!F12+MSU!F12+Michigan!F12+Wisconsin!F12+Maryland!F12+Rutgers!F12+Illinois!F12+USC!F12+UCLA!F12+Purdue!F12 -> 22 | G12: =Louisville!G12+SD!G12+ND!G12+Alabama!G12+UNO!G12+KSU!G12+Indiana!G12+Iowa!G12+Washington!G12+MSU!G12+Michigan!G12+Wisconsin!G12+Maryland!G12+Rutgers!G12+Illinois!G12+USC!G12+UCLA!G12+Purdue!G12 -> 1 | H12: =Louisville!H12+SD!H12+ND!H12+Alabama!H12+UNO!H12+KSU!H12+Indiana!H12+Iowa!H12+Washington!H12+MSU!H12+Michigan!H12+Wisconsin!H12+Maryland!H12+Rutgers!H12+Illinois!H12+USC!H12+UCLA!H12+Purdue!H12 -> 1 | I12: =Louisville!I12+SD!I12+ND!I12+Alabama!I12+UNO!I12+KSU!I12+Indiana!I12+Iowa!I12+Washington!I12+MSU!I12+Michigan!I12+Wisconsin!I12+Maryland!I12+Rutgers!I12+Illinois!I12+USC!I12+UCLA!I12+Purdue!I12 -> 10 | ... N12: =Louisville!N12+SD!N12+ND!N12+Alabama!N12+UNO!N12+KSU!N12+Indiana!N12+Iowa!N12+Washington!N12+MSU!N12+Michigan!N12+Wisconsin!N12+Maryland!N12+Rutgers!N12+Illinois!N12+USC!N12+UCLA!N12+Purdue!N12 -> 38 | O12: =IFERROR(N12/B12,0) -> 0.11111111 | P12: =Louisville!P12+SD!P12+ND!P12+Alabama!P12+UNO!P12+KSU!P12+Indiana!P12+Iowa!P12+Washington!P12+MSU!P12+Michigan!P12+Wisconsin!P12+Maryland!P12+Rutgers!P12+Illinois!P12+USC!P12+UCLA!P12+Purdue!P12 -> 24 | Q12: =Louisville!Q12+SD!Q12+ND!Q12+Alabama!Q12+UNO!Q12+KSU!Q12+Indiana!Q12+Iowa!Q12+Washington!Q12+MSU!Q12+Michigan!Q12+Wisconsin!Q12+Maryland!Q12+Rutgers!Q12+Illinois!Q12+USC!Q12+UCLA!Q12+Purdue!Q12 -> 14 | R12: =Louisville!R12+SD!R12+ND!R12+Alabama!R12+UNO!R12+KSU!R12+Indiana!R12+Iowa!R12+Washington!R12+MSU!R12+Michigan!R12+Wisconsin!R12+Maryland!R12+Rutgers!R12+Illinois!R12+USC!R12+UCLA!R12+Purdue!R12 -> 11 | S12: =Louisville!S12+SD!S12+ND!S12+Alabama!S12+UNO!S12+KSU!S12+Indiana!S12+Iowa!S12+Washington!S12+MSU!S12+Michigan!S12+Wisconsin!S12+Maryland!S12+Rutgers!S12+Illinois!S12+USC!S12+UCLA!S12+Purdue!S12 -> 1 | T12: =Louisville!T12+SD!T12+ND!T12+Alabama!T12+UNO!T12+KSU!T12+Indiana!T12+Iowa!T12+Washington!T12+MSU!T12+Michigan!T12+Wisconsin!T12+Maryland!T12+Rutgers!T12+Illinois!T12+USC!T12+UCLA!T12+Purdue!T12 -> 0 | U12: =Louisville!U12+SD!U12+ND!U12+Alabama!U12+UNO!U12+KSU!U12+Indiana!U12+Iowa!U12+Washington!U12+MSU!U12+Michigan!U12+Wisconsin!U12+Maryland!U12+Rutgers!U12+Illinois!U12+USC!U12+UCLA!U12+Purdue!U12 -> 6 | V12: =Louisville!V12+SD!V12+ND!V12+Alabama!V12+UNO!V12+KSU!V12+Indiana!V12+Iowa!V12+Washington!V12+MSU!V12+Michigan!V12+Wisconsin!V12+Maryland!V12+Rutgers!V12+Illinois!V12+USC!V12+UCLA!V12+Purdue!V12 -> 4 | W12: =Louisville!W12+SD!W12+ND!W12+Alabama!W12+UNO!W12+KSU!W12+Indiana!W12+Iowa!W12+Washington!W12+MSU!W12+Michigan!W12+Wisconsin!W12+Maryland!W12+Rutgers!W12+Illinois!W12+USC!W12+UCLA!W12+Purdue!W12 -> 18 | X12: =Louisville!X12+SD!X12+ND!X12+Alabama!X12+UNO!X12+KSU!X12+Indiana!X12+Iowa!X12+Washington!X12+MSU!X12+Michigan!X12+Wisconsin!X12+Maryland!X12+Rutgers!X12+Illinois!X12+USC!X12+UCLA!X12+Purdue!X12 -> 78 | Y12: =IFERROR(X12/B12,0) -> 0.22807018 | Z12: =Louisville!Z12+SD!Z12+ND!Z12+Alabama!Z12+UNO!Z12+KSU!Z12+Indiana!Z12+Iowa!Z12+Washington!Z12+MSU!Z12+Michigan!Z12+Wisconsin!Z12+Maryland!Z12+Rutgers!Z12+Illinois!Z12+USC!Z12+UCLA!Z12+Purdue!Z12 -> 116 | AA12: =IFERROR(Z12/B12,0) -> 0.33918129 | AC12: ="<tr><td>Reda</td><td>"&B12&"</td><td>"&C12&"</td><td>"&D12&"</td><td>"&E12&"</td><td>"&F12&"</td><td>"&G12&"</td><td>"&H12&"</td><td>"&I12&"</td><td>"&J12&"</td><td>"&K12&"</td><td>"&L12&"</td><td>"&M12&"</td><td>"&N12&"</td><td>"&TEXT(O12,"0.00")&"</td><td>"&Z12&"</td><td>"&TEXT(AA12,"0.00")&"</td></tr>" -> <tr><td>Reda</td><td>342</td><td>0</td><td>0</td><td>0</td><td>22</td><td>1</td><td>1</td><td>10</td><td>1</td><td>3</td><td>1</td><td>0</td><td>38</td><td>0.11</td><td>116</td><td>0.34</td></tr> | AT12: ="<tr><td>Reda</td><td>"&B12&"</td><td>"&P12&"</td><td>"&Q12&"</td><td>"&R12&"</td><td>"&S12&"</td><td>"&T12&"</td><td>"&U12&"</td><td>"&V12&"</td><td>"&W12&"</td><td>"&X12&"</td><td>"&TEXT(Y12,"0.00")&"</td><td>"&Z12&"</td><td>"&TEXT(AA12,"0.00")&"</td></tr>" -> <tr><td>Reda</td><td>342</td><td>24</td><td>14</td><td>11</td><td>1</td><td>0</td><td>6</td><td>4</td><td>18</td><td>78</td><td>0.23</td><td>116</td><td>0.34</td></tr>
A13: izzie | B13: =Louisville!B13+SD!B13+ND!B13+Alabama!B13+UNO!B13+KSU!B13+Indiana!B13+Iowa!B13+Washington!B13+MSU!B13+Michigan!B13+Wisconsin!B13+Maryland!B13+Rutgers!B13+Illinois!B13+USC!B13+UCLA!B13+Purdue!B13 -> 13 | C13: =Louisville!C13+SD!C13+ND!C13+Alabama!C13+UNO!C13+KSU!C13+Indiana!C13+Iowa!C13+Washington!C13+MSU!C13+Michigan!C13+Wisconsin!C13+Maryland!C13+Rutgers!C13+Illinois!C13+USC!C13+UCLA!C13+Purdue!C13 -> 0 | D13: =Louisville!D13+SD!D13+ND!D13+Alabama!D13+UNO!D13+KSU!D13+Indiana!D13+Iowa!D13+Washington!D13+MSU!D13+Michigan!D13+Wisconsin!D13+Maryland!D13+Rutgers!D13+Illinois!D13+USC!D13+UCLA!D13+Purdue!D13 -> 0 | E13: =Louisville!E13+SD!E13+ND!E13+Alabama!E13+UNO!E13+KSU!E13+Indiana!E13+Iowa!E13+Washington!E13+MSU!E13+Michigan!E13+Wisconsin!E13+Maryland!E13+Rutgers!E13+Illinois!E13+USC!E13+UCLA!E13+Purdue!E13 -> 0 | F13: =Louisville!F13+SD!F13+ND!F13+Alabama!F13+UNO!F13+KSU!F13+Indiana!F13+Iowa!F13+Washington!F13+MSU!F13+Michigan!F13+Wisconsin!F13+Maryland!F13+Rutgers!F13+Illinois!F13+USC!F13+UCLA!F13+Purdue!F13 -> 0 | G13: =Louisville!G13+SD!G13+ND!G13+Alabama!G13+UNO!G13+KSU!G13+Indiana!G13+Iowa!G13+Washington!G13+MSU!G13+Michigan!G13+Wisconsin!G13+Maryland!G13+Rutgers!G13+Illinois!G13+USC!G13+UCLA!G13+Purdue!G13 -> 0 | H13: =Louisville!H13+SD!H13+ND!H13+Alabama!H13+UNO!H13+KSU!H13+Indiana!H13+Iowa!H13+Washington!H13+MSU!H13+Michigan!H13+Wisconsin!H13+Maryland!H13+Rutgers!H13+Illinois!H13+USC!H13+UCLA!H13+Purdue!H13 -> 0 | I13: =Louisville!I13+SD!I13+ND!I13+Alabama!I13+UNO!I13+KSU!I13+Indiana!I13+Iowa!I13+Washington!I13+MSU!I13+Michigan!I13+Wisconsin!I13+Maryland!I13+Rutgers!I13+Illinois!I13+USC!I13+UCLA!I13+Purdue!I13 -> 0 | ... N13: =Louisville!N13+SD!N13+ND!N13+Alabama!N13+UNO!N13+KSU!N13+Indiana!N13+Iowa!N13+Washington!N13+MSU!N13+Michigan!N13+Wisconsin!N13+Maryland!N13+Rutgers!N13+Illinois!N13+USC!N13+UCLA!N13+Purdue!N13 -> 0 | O13: =IFERROR(N13/B13,0) -> 0 | P13: =Louisville!P13+SD!P13+ND!P13+Alabama!P13+UNO!P13+KSU!P13+Indiana!P13+Iowa!P13+Washington!P13+MSU!P13+Michigan!P13+Wisconsin!P13+Maryland!P13+Rutgers!P13+Illinois!P13+USC!P13+UCLA!P13+Purdue!P13 -> 0 | Q13: =Louisville!Q13+SD!Q13+ND!Q13+Alabama!Q13+UNO!Q13+KSU!Q13+Indiana!Q13+Iowa!Q13+Washington!Q13+MSU!Q13+Michigan!Q13+Wisconsin!Q13+Maryland!Q13+Rutgers!Q13+Illinois!Q13+USC!Q13+UCLA!Q13+Purdue!Q13 -> 0 | R13: =Louisville!R13+SD!R13+ND!R13+Alabama!R13+UNO!R13+KSU!R13+Indiana!R13+Iowa!R13+Washington!R13+MSU!R13+Michigan!R13+Wisconsin!R13+Maryland!R13+Rutgers!R13+Illinois!R13+USC!R13+UCLA!R13+Purdue!R13 -> 0 | S13: =Louisville!S13+SD!S13+ND!S13+Alabama!S13+UNO!S13+KSU!S13+Indiana!S13+Iowa!S13+Washington!S13+MSU!S13+Michigan!S13+Wisconsin!S13+Maryland!S13+Rutgers!S13+Illinois!S13+USC!S13+UCLA!S13+Purdue!S13 -> 0 | T13: =Louisville!T13+SD!T13+ND!T13+Alabama!T13+UNO!T13+KSU!T13+Indiana!T13+Iowa!T13+Washington!T13+MSU!T13+Michigan!T13+Wisconsin!T13+Maryland!T13+Rutgers!T13+Illinois!T13+USC!T13+UCLA!T13+Purdue!T13 -> 0 | U13: =Louisville!U13+SD!U13+ND!U13+Alabama!U13+UNO!U13+KSU!U13+Indiana!U13+Iowa!U13+Washington!U13+MSU!U13+Michigan!U13+Wisconsin!U13+Maryland!U13+Rutgers!U13+Illinois!U13+USC!U13+UCLA!U13+Purdue!U13 -> 0 | V13: =Louisville!V13+SD!V13+ND!V13+Alabama!V13+UNO!V13+KSU!V13+Indiana!V13+Iowa!V13+Washington!V13+MSU!V13+Michigan!V13+Wisconsin!V13+Maryland!V13+Rutgers!V13+Illinois!V13+USC!V13+UCLA!V13+Purdue!V13 -> 0 | W13: =Louisville!W13+SD!W13+ND!W13+Alabama!W13+UNO!W13+KSU!W13+Indiana!W13+Iowa!W13+Washington!W13+MSU!W13+Michigan!W13+Wisconsin!W13+Maryland!W13+Rutgers!W13+Illinois!W13+USC!W13+UCLA!W13+Purdue!W13 -> 0 | X13: =Louisville!X13+SD!X13+ND!X13+Alabama!X13+UNO!X13+KSU!X13+Indiana!X13+Iowa!X13+Washington!X13+MSU!X13+Michigan!X13+Wisconsin!X13+Maryland!X13+Rutgers!X13+Illinois!X13+USC!X13+UCLA!X13+Purdue!X13 -> 0 | Y13: =IFERROR(X13/B13,0) -> 0 | Z13: =Louisville!Z13+SD!Z13+ND!Z13+Alabama!Z13+UNO!Z13+KSU!Z13+Indiana!Z13+Iowa!Z13+Washington!Z13+MSU!Z13+Michigan!Z13+Wisconsin!Z13+Maryland!Z13+Rutgers!Z13+Illinois!Z13+USC!Z13+UCLA!Z13+Purdue!Z13 -> 0 | AA13: =IFERROR(Z13/B13,0) -> 0 | AC13: ="<tr><td>Kiser</td><td>"&B13&"</td><td>"&C13&"</td><td>"&D13&"</td><td>"&E13&"</td><td>"&F13&"</td><td>"&G13&"</td><td>"&H13&"</td><td>"&I13&"</td><td>"&J13&"</td><td>"&K13&"</td><td>"&L13&"</td><td>"&M13&"</td><td>"&N13&"</td><td>"&TEXT(O13,"0.00")&"</td><td>"&Z13&"</td><td>"&TEXT(AA13,"0.00")&"</td></tr>" -> <tr><td>Kiser</td><td>13</td><td>0</td><td>0</td><td>0</td><td>0</td><td>0</td><td>0</td><td>0</td><td>0</td><td>0</td><td>0</td><td>0</td><td>0</td><td>0.00</td><td>0</td><td>0.00</td></tr> | AT13: ="<tr><td>Kiser</td><td>"&B13&"</td><td>"&P13&"</td><td>"&Q13&"</td><td>"&R13&"</td><td>"&S13&"</td><td>"&T13&"</td><td>"&U13&"</td><td>"&V13&"</td><td>"&W13&"</td><td>"&X13&"</td><td>"&TEXT(Y13,"0.00")&"</td><td>"&Z13&"</td><td>"&TEXT(AA13,"0.00")&"</td></tr>" -> <tr><td>Kiser</td><td>13</td><td>0</td><td>0</td><td>0</td><td>0</td><td>0</td><td>0</td><td>0</td><td>0</td><td>0</td><td>0.00</td><td>0</td><td>0.00</td></tr>
